Workbook

Sheet raw_data
A1: subj | B1: include | C1: site | D1: gender | E1: birthdate | F1: test_date | G1: age | H1: age_at_diagnosis | I1: duration | J1: nationality | K1: marital_status | L1: religion_belief_worldview | M1: Housing_situation | N1: Cohabitation | O1: Nursing_support | P1: Residential_location | Q1: School_graduation | R1: Professional_education | S1: Advance_directive | T1: Power_of_attorney | U1: other_document | V1: palliative_care_knowledge | W1: hospice_knowledge | X1: thoughts_about_end_of_life_wishes | Y1: Sharing_of_thoughts | Z1: Thoughts_dicussed_with | AA1: asked_about_end_of_life_wishes | AB1: asked_by_whom | AC1: preferred_place_of_care | AD1: preferred_place_of_death | AE1: POD_family_friends | AF1: POD_GP | AG1: POD_neurologist | AH1: POD_AD | AI1: LEDD | AJ1: Levodopa/Carbidopa | AK1: Levodopa/Carbidopa CR | AL1: Entacapone | AM1: Tolcapone | AN1: Pramipexole | AO1: Ropinirole | AP1: Rotigotine | AQ1: Selegiline, oral | AR1: Selegiline, sublingual | AS1: Rasagiline | AT1: Amantadine | AU1: Apomorphine | AV1: Piribedil | AW1: Safinamid | AX1: Opicapon | AY1: Hoehn_Yahr | AZ1: PDQ_1 | BA1: PDQ_2 | BB1: PDQ_3 | BC1: PDQ_4 | BD1: PDQ_5 | BE1: PDQ_6 | BF1: PDQ_7 | BG1: PDQ_8 | BH1: PDQ_9 | BI1: PDQ_10 | BJ1: PDQ_11 | BK1: PDQ_12 | BL1: PDQ_13 | BM1: PDQ_14 | BN1: PDQ_15 | BO1: PDQ_16 | BP1: PDQ_17 | BQ1: PDQ_18 | BR1: PDQ_19 | BS1: PDQ_20 | BT1: PDQ_21 | BU1: PDQ_22 | BV1: PDQ_23 | BW1: PDQ_24 | BX1: PDQ_25 | BY1: PDQ_26 | BZ1: PDQ_27 | CA1: PDQ_28 | CB1: PDQ_29 | CC1: PDQ_30 | CD1: PDQ_31 | CE1: PDQ_32 | CF1: PDQ_33 | CG1: PDQ_34 | CH1: PDQ_35 | CI1: PDQ_36 | CJ1: PDQ_37 | CK1: PDQ_38 | CL1: PDQ_39 | CM1: Mobility | CN1: ADL | CO1: EmotionalWEllbeing | CP1: stigma | CQ1: SocialSupport | CR1: Cognition | CS1: Communication | CT1: BodilyDiscomfort | CV1: UPDRS_1_1 | CW1: UPDRS_1_2 | CX1: UPDRS_1_3 | CY1: UPDRS_1_4 | CZ1: UPDRS_1_5 | DA1: UPDRS_1_6 | DB1: UPDRS_1a_source | DC1: UPDRS_1_7 | DD1: UPDRS_1_8 | DE1: UPDRS_1_9 | DF1: UPDRS_1_10 | DG1: UPDRS_1_11 | DH1: UPDRS_1_12 | DI1: UPDRS_1_13 | DJ1: UPDRS_1b_source | DK1: updrs_I | DL1: UPDRS_2_1 | DM1: UPDRS_2_2 | DN1: UPDRS_2_3 | DO1: UPDRS_2_4 | DP1: UPDRS_2_5 | DQ1: UPDRS_2_6 | DR1: UPDRS_2_7 | DS1: UPDRS_2_8 | DT1: UPDRS_2_9 | DU1: UPDRS_2_10 | DV1: UPDRS_2_11 | DW1: UPDRS_2_12 | DX1: UPDRS_2_13 | DY1: updrs_II | DZ1: UPDRS_3_1 | EA1: UPDRS_3_2 | EB1: UPDRS_3_3_Nacken | EC1: UPDRS_3_3_ROE | ED1: UPDRS_3_3_LOE | EE1: UPDRS_3_3_RUE | EF1: UPDRS_3_3_LUE | EG1: UPDRS_3_4_R | EH1: UPDRS_3_4_L | EI1: UPDRS_3_5_R | EJ1: UPDRS_3_5_L | EK1: UPDRS_3_6_R | EL1: UPDRS_3_6_L | EM1: UPDRS_3_7_R | EN1: UPDRS_3_7_L | EO1: UPDRS_3_8_R | EP1: UPDRS_3_8_L | EQ1: UPDRS_3_9 | ER1: UPDRS_3_10 | ES1: UPDRS_3_11 | ET1: UPDRS_3_12 | EU1: UPDRS_3_13 | EV1: UPDRS_3_14 | EW1: UPDRS_3_15_R | EX1: UPDRS_3_15_L | EY1: UPDRS_3_16_R | EZ1: UPDRS_3_16_L | FA1: UPDRS_3_17_ROE | FB1: UPDRS_3_17_LOE | FC1: UPDRS_3_17_RUE | FD1: UPDRS_3_17_LUE | FE1: UPDRS_3_17_lip_jaw | FF1: UPDRS_3_18 | FG1: updrs_III | FH1: UPDRS_4_1 | FI1: UPDRS_4_2 | FJ1: UPDRS_4_3 | FK1: UPDRS_4_4 | FL1: UPDRS_4_5 | FM1: UPDRS_4_6 | FN1: updrs_IV | FO1: UPDRS_sum | FP1: bdi_score | FQ1: MOCA_VISUOSPATIAL | FR1: MOCA_NAMING | FS1: MOCA_Attention | FT1: MOCA_language | FU1: MOCA_abstraction | FV1: MOCA_RECALL | FW1: MOCA_Orientation | FX1: MOCA_score | FY1: Charlson_withoutage | FZ1: Charlson_withage | GA1: dbs
A2: 1 | B2: 1 | C2: 1 | D2: 0 | E2: 23843 | F2: 44347 | G2: =DATEDIF(E2,F2,"M")/12 -> 56.083333 | H2: 53 | I2: =G2-H2 -> 3.0833333 | J2: 0 | K2: 3 | L2: 1 | M2: 0 | N2: 2 | O2: 0 | P2: 2 | Q2: 2 | R2: 1 | S2: 1 | T2: 1 | U2: 0 | V2: 1 | W2: 1 | X2: 2 | Y2: 3 | Z2: 1 | AA2: 3 | AB2: 1 | AC2: 0 | AD2: 0 | AE2: 0 | AF2: 0 | AG2: 0 | AH2: 0 | AI2: =AJ2*ledd!$B$2+AK2*ledd!$B$3+AL2*ledd!$B$4+AM2*ledd!$B$5+AN2*ledd!$B$6+AO2*ledd!$B$7+AP2*ledd!$B$8+AQ2*ledd!$B$9+AR2*ledd!$B$10+AS2*ledd!$B$11+AT2*ledd!$B$12+AU2*ledd!$B$13+AV2*ledd!$B$14+AW2*ledd!$B$15+AX2*ledd!$B$16 -> 665 | AJ2: 100 | AK2: 300 | AL2: 0 | AM2: 0 | AN2: 0 | AO2: 0 | AP2: 8 | AQ2: 0 | AR2: 0 | AS2: 1 | AT2: 0 | AU2: 0 | AV2: 0 | AW2: 0 | AX2: 0 | AY2: 4 | AZ2: 2 | BA2: 1 | BB2: 1 | BC2: 3 | BD2: 1 | BE2: 1 | BF2: 2 | BG2: 2 | BH2: 2 | BI2: 2 | BJ2: 1 | BK2: 1 | BL2: 1 | BM2: 2 | BN2: 1 | BO2: 1 | BP2: 2 | BQ2: 3 | BR2: 2 | BS2: 3 | BT2: 2 | BU2: 1 | BV2: 1 | BW2: 1 | BX2: 1 | BY2: 1 | BZ2: 2 | CA2: 1 | CB2: 1 | CC2: 1 | CD2: 1 | CE2: 1 | CF2: 1 | CG2: 3 | CH2: 3 | CI2: 1 | CJ2: 1 | CK2: 2 | CL2: 1 | CM2: =(SUM(AZ2:BI2)*100/40) -> 42.5 | CN2: =SUM(BJ2:BO2)*100/24 -> 29.166667 | CO2: =SUM(BP2:BU2)*100/24 -> 54.166667 | CP2: =SUM(BV2:BY2)*100/16 -> 25 | CQ2: =SUM(BZ2:CB2)*100/12 -> 33.333333 | CR2: =SUM(CC2:CF2)*100/16 -> 25 | CS2: =SUM(CG2:CI2)*100/12 -> 58.333333 | CT2: =SUM(CJ2:CL2)*100/12 -> 33.333333 | CU2: =SUM(CM2:CT2)/8 -> 37.604167 | CV2: 0 | CW2: 0 | CX2: 3 | CY2: 1 | CZ2: 0 | DA2: 0 | DB2: 0 | DC2: 0 | DD2: 0 | DE2: 1 | DF2: 0 | DG2: 0 | DH2: 3 | DI2: 0 | DJ2: 0 | DK2: =SUM(CV2:DA2,DC2:DI2) -> 8 | DL2: 0 | DM2: 2 | DN2: 2 | DO2: 0 | DP2: 1 | DQ2: 0 | DR2: 1 | DS2: 4 | DT2: 4 | DU2: 3 | DV2: 0 | DW2: 4 | DX2: 0 | DY2: 21 | DZ2: 1 | EA2: 1 | EB2: 0 | EC2: 0 | ED2: 0 | EE2: 1 | EF2: 1 | EG2: 0 | EH2: 0 | EI2: 0 | EJ2: 0 | EK2: 0 | EL2: 0 | EM2: 2 | EN2: 2 | EO2: 0 | EP2: 0 | EQ2: 0 | ER2: 3 | ES2: 3 | ET2: 3 | EU2: 0 | EV2: 0 | EW2: 0 | EX2: 0 | EY2: 0 | EZ2: 0 | FA2: 0 | FB2: 0 | FC2: 0 | FD2: 0 | FE2: 0 | FF2: 0 | FG2: =SUM(DZ2:FF2) -> 17 | FH2: 0 | FI2: 0 | FJ2: 0 | FK2: 1 | FL2: 0 | FM2: 0 | FN2: =SUM(FH2:FM2) -> 1 | FO2: =SUM(DK2,DY2,FG2,FN2) -> 47 | FP2: 5 | FQ2: 5 | FR2: 3 | FS2: 6 | FT2: 3 | FU2: 2 | FV2: 4 | FW2: 6 | FX2: =SUM(FQ2:FW2) -> 29 | FY2: 0 | FZ2: =IF($G2<=50,$FY2+0,IF(AND($G2<60,$G2>50),$FY2+1,IF(AND($G2<70,$G2>60),$FY2+2,IF(AND($G2<80,$G2>70),$FY2+3,IF(AND($G2<90,$G2>80),$FY2+4,IF($G2>=90,$FY2+5,"")))))) -> 1 | GA2: 1
A3: 2 | B3: 1 | C3: 1 | D3: 1 | E3: 21078 | F3: 44348 | G3: =DATEDIF(E3,F3,"M")/12 -> 63.666667 | H3: 50 | I3: =G3-H3 -> 13.666667 | J3: 0 | K3: 1 | L3: 0 | M3: 0 | N3: 3 | O3: 1 | P3: 4 | Q3: 2 | R3: 1 | S3: 1 | T3: 1 | U3: 0 | V3: 1 | W3: 1 | X3: 3 | Y3: 3 | Z3: 0 | AA3: 3 | AB3: 0 | AC3: 0 | AD3: 0 | AE3: 1 | AF3: 0 | AG3: 0 | AH3: 0 | AI3: =AJ3*ledd!$B$2+AK3*ledd!$B$3+AL3*ledd!$B$4+AM3*ledd!$B$5+AN3*ledd!$B$6+AO3*ledd!$B$7+AP3*ledd!$B$8+AQ3*ledd!$B$9+AR3*ledd!$B$10+AS3*ledd!$B$11+AT3*ledd!$B$12+AU3*ledd!$B$13+AV3*ledd!$B$14+AW3*ledd!$B$15+AX3*ledd!$B$16 -> 820 | AJ3: 600 | AK3: 200 | AL3: 0 | AM3: 0 | AN3: 0.7 | AO3: 0 | AP3: 0 | AQ3: 0 | AR3: 0 | AS3: 0 | AT3: 0 | AU3: 0 | AV3: 0 | AW3: 0 | AX3: 0 | AY3: 4 | AZ3: 1 | BA3: 2 | BB3: 2 | BC3: 0 | BD3: 0 | BE3: 0 | BF3: 0 | BG3: 0 | BH3: 1 | BI3: 0 | BJ3: 2 | BK3: 2 | BL3: 3 | BM3: 3 | BN3: 3 | BO3: 3 | BP3: 0 | BQ3: 0 | BR3: 1 | BS3: 2 | BT3: 0 | BU3: 3 | BV3: 1 | BW3: 2 | BX3: 0 | BY3: 2 | BZ3: 0 | CA3: 0 | CB3: 0 | CC3: 0 | CD3: 2 | CE3: 0 | CF3: 0 | CG3: 2 | CH3: 1 | CI3: 2 | CJ3: 0 | CK3: 0 | CL3: 2 | CM3: =(SUM(AZ3:BI3)*100/40) -> 15 | CN3: =SUM(BJ3:BO3)*100/24 -> 66.666667 | CO3: =SUM(BP3:BU3)*100/24 -> 25 | CP3: =SUM(BV3:BY3)*100/16 -> 31.25 | CQ3: =SUM(BZ3:CB3)*100/12 -> 0 | CR3: =SUM(CC3:CF3)*100/16 -> 12.5 | CS3: =SUM(CG3:CI3)*100/12 -> 41.666667 | CT3: =SUM(CJ3:CL3)*100/12 -> 16.666667 | CU3: =SUM(CM3:CT3)/8 -> 26.09375 | CV3: 0 | CW3: 0 | CX3: 0 | CY3: 0 | CZ3: 0 | DA3: 0 | DB3: 0 | DC3: 3 | DD3: 3 | DE3: 0 | DF3: 2 | DG3: 1 | DH3: 1 | DI3: 0 | DJ3: 0 | DK3: =SUM(CV3:DA3,DC3:DI3) -> 10 | DL3: 1 | DM3: 2 | DN3: 1 | DO3: 1 | DP3: 2 | DQ3: 2 | DR3: 3 | DS3: 1 | DT3: 2 | DU3: 3 | DV3: 1 | DW3: 2 | DX3: 2 | DY3: =SUM(DL3:DX3) -> 23 | DZ3: 2 | EA3: 3 | EB3: 2 | EC3: 2 | ED3: 3 | EE3: 2 | EF3: 2 | EG3: 2 | EH3: 3 | EI3: 2 | EJ3: 3 | EK3: 3 | EL3: 4 | EM3: 2 | EN3: 3 | EO3: 2 | EP3: 3 | EQ3: 0 | ER3: 3 | ES3: 1 | ET3: 3 | EU3: 3 | EV3: 3 | EW3: 1 | EX3: 3 | EY3: 1 | EZ3: 2 | FA3: 1 | FB3: 3 | FC3: 0 | FD3: 0 | FE3: 0 | FF3: 4 | FG3: =SUM(DZ3:FF3) -> 71 | FH3: 2 | FI3: 1 | FJ3: 1 | FK3: 2 | FL3: 1 | FM3: 1 | FN3: =SUM(FH3:FM3) -> 8 | FO3: =SUM(DK3,DY3,FG3,FN3) -> 112 | FP3: 11 | FQ3: 4 | FR3: 3 | FS3: 6 | FT3: 3 | FU3: 1 | FV3: 5 | FW3: 5 | FX3: =SUM(FQ3:FW3) -> 27 | FY3: 0 | FZ3: =IF($G3<=50,$FY3+0,IF(AND($G3<60,$G3>50),$FY3+1,IF(AND($G3<70,$G3>60),$FY3+2,IF(AND($G3<80,$G3>70),$FY3+3,IF(AND($G3<90,$G3>80),$FY3+4,IF($G3>=90,$FY3+5,"")))))) -> 2 | GA3: 1
A4: 3 | B4: 1 | C4: 1 | D4: 1 | E4: 16345 | F4: 44348 | G4: =DATEDIF(E4,F4,"M")/12 -> 76.666667 | H4: 69 | I4: =G4-H4 -> 7.6666667 | J4: 0 | K4: 1 | L4: 1 | M4: 0 | N4: 2 | O4: 0 | P4: 1 | Q4: 3 | R4: 1 | S4: 1 | T4: 1 | U4: 0 | V4: 1 | W4: 1 | X4: 2 | Y4: 2 | Z4: 0 | AA4: 2 | AB4: 0 | AC4: 0 | AD4: 0 | AE4: 1 | AF4: 1 | AG4: 0 | AH4: 1 | AI4: =AJ4*ledd!$B$2+AK4*ledd!$B$3+AL4*ledd!$B$4+AM4*ledd!$B$5+AN4*ledd!$B$6+AO4*ledd!$B$7+AP4*ledd!$B$8+AQ4*ledd!$B$9+AR4*ledd!$B$10+AS4*ledd!$B$11+AT4*ledd!$B$12+AU4*ledd!$B$13+AV4*ledd!$B$14+AW4*ledd!$B$15+AX4*ledd!$B$16 -> 320 | AJ4: 0 | AK4: 0 | AL4: 0 | AM4: 0 | AN4: 0 | AO4: 6 | AP4: 0 | AQ4: 0 | AR4: 0 | AS4: 1 | AT4: 100 | AU4: 0 | AV4: 0 | AW4: 0 | AX4: 0 | AY4: 4 | AZ4: 2 | BA4: 1 | BB4: 0 | BC4: 0 | BD4: 0 | BE4: 1 | BF4: 0 | BG4: 1 | BH4: 0 | BI4: 3 | BJ4: 0 | BK4: 0 | BL4: 4 | BM4: 4 | BN4: 0 | BO4: 0 | BP4: 0 | BQ4: 0 | BR4: 2 | BS4: 0 | BT4: 0 | BU4: 1 | BV4: 0 | BW4: 1 | BX4: 0 | BY4: 0 | BZ4: 0 | CA4: 0 | CB4: 0 | CC4: 0 | CD4: 0 | CE4: 0 | CF4: 0 | CG4: 2 | CH4: 0 | CI4: 0 | CJ4: 2 | CK4: 3 | CL4: 0 | CM4: =(SUM(AZ4:BI4)*100/40) -> 20 | CN4: =SUM(BJ4:BO4)*100/24 -> 33.333333 | CO4: =SUM(BP4:BU4)*100/24 -> 12.5 | CP4: =SUM(BV4:BY4)*100/16 -> 6.25 | CQ4: =SUM(BZ4:CB4)*100/12 -> 0 | CR4: =SUM(CC4:CF4)*100/16 -> 0 | CS4: =SUM(CG4:CI4)*100/12 -> 16.666667 | CT4: =SUM(CJ4:CL4)*100/12 -> 41.666667 | CU4: =SUM(CM4:CT4)/8 -> 16.302083 | CV4: 0 | CW4: 0 | CX4: 0 | CY4: 0 | CZ4: 0 | DA4: 0 | DB4: 0 | DC4: 0 | DD4: 0 | DE4: 2 | DF4: 0 | DG4: 2 | DH4: 0 | DI4: 0 | DJ4: 0 | DK4: =SUM(CV4:DA4,DC4:DI4) -> 4 | DL4: 1 | DM4: 1 | DN4: 0 | DO4: 0 | DP4: 2 | DQ4: 0 | DR4: 3 | DS4: 3 | DT4: 1 | DU4: 0 | DV4: 0 | DW4: 2 | DX4: 3 | DY4: =SUM(DL4:DX4) -> 16 | DZ4: 1 | EA4: 2 | EB4: 4 | EC4: 2 | ED4: 2 | EE4: 2 | EF4: 2 | EG4: 3 | EH4: 3 | EI4: 3 | EJ4: 3 | EK4: 3 | EL4: 4 | EM4: 3 | EN4: 3 | EO4: 3 | EP4: 3 | EQ4: 2 | ER4: 2 | ES4: 1 | ET4: 2 | EU4: 4 | EV4: 3 | EW4: 1 | EX4: 0 | EY4: 0 | EZ4: 0 | FA4: 0 | FB4: 0 | FC4: 0 | FD4: 0 | FE4: 0 | FF4: 0 | FG4: =SUM(DZ4:FF4) -> 61 | FH4: 0 | FI4: 0 | FJ4: 2 | FK4: 2 | FL4: 1 | FM4: 1 | FN4: =SUM(FH4:FM4) -> 6 | FO4: =SUM(DK4,DY4,FG4,FN4) -> 87 | FP4: 9 | FQ4: 5 | FR4: 3 | FS4: 6 | FT4: 1 | FU4: 2 | FV4: 1 | FW4: 5 | FX4: =SUM(FQ4:FW4) -> 23 | FY4: 6 | FZ4: =IF($G4<=50,$FY4+0,IF(AND($G4<60,$G4>50),$FY4+1,IF(AND($G4<70,$G4>60),$FY4+2,IF(AND($G4<80,$G4>70),$FY4+3,IF(AND($G4<90,$G4>80),$FY4+4,IF($G4>=90,$FY4+5,"")))))) -> 9 | GA4: 1
A5: 4 | B5: 1 | C5: 1 | D5: 1 | E5: 23004 | F5: 44353 | G5: =DATEDIF(E5,F5,"M")/12 -> 58.416667 | H5: 55 | I5: =G5-H5 -> 3.4166667 | J5: 0 | K5: 1 | L5: 8 | M5: 0 | N5: 6 | O5: 0 | P5: 4 | Q5: 4 | R5: 3 | S5: 0 | T5: 0 | U5: 0 | V5: 1 | W5: 1 | X5: 0 | Y5: 0 | AA5: 0 | AC5: 6 | AD5: 6 | AE5: 0 | AF5: 0 | AG5: 0 | AH5: 0 | AI5: =AJ5*ledd!$B$2+AK5*ledd!$B$3+AL5*ledd!$B$4+AM5*ledd!$B$5+AN5*ledd!$B$6+AO5*ledd!$B$7+AP5*ledd!$B$8+AQ5*ledd!$B$9+AR5*ledd!$B$10+AS5*ledd!$B$11+AT5*ledd!$B$12+AU5*ledd!$B$13+AV5*ledd!$B$14+AW5*ledd!$B$15+AX5*ledd!$B$16 -> 450 | AJ5: 300 | AK5: 0 | AL5: 0 | AM5: 0 | AN5: 0 | AO5: 0 | AP5: 0 | AQ5: 0 | AR5: 0 | AS5: 0 | AT5: 0 | AU5: 0 | AV5: 150 | AW5: 0 | AX5: 0 | AY5: 2 | AZ5: 3 | BA5: 0 | BB5: 0 | BC5: 4 | BD5: 3 | BE5: 0 | BF5: 3 | BG5: 0 | BH5: 0 | BI5: 3 | BJ5: 0 | BK5: 0 | BL5: 0 | BM5: 3 | BN5: 0 | BO5: 0 | BP5: 3 | BQ5: 2 | BR5: 2 | BS5: 1 | BT5: 0 | BU5: 3 | BV5: 3 | BW5: 0 | BX5: 2 | BY5: 2 | BZ5: 0 | CA5: 0 | CB5: 0 | CC5: 0 | CD5: 4 | CE5: 2 | CF5: 0 | CG5: 1 | CH5: 2 | CI5: 0 | CJ5: 3 | CK5: 2 | CL5: 0 | CM5: =(SUM(AZ5:BI5)*100/40) -> 40 | CN5: =SUM(BJ5:BO5)*100/24 -> 12.5 | CO5: =SUM(BP5:BU5)*100/24 -> 45.833333 | CP5: =SUM(BV5:BY5)*100/16 -> 43.75 | CQ5: =SUM(BZ5:CB5)*100/12 -> 0 | CR5: =SUM(CC5:CF5)*100/16 -> 37.5 | CS5: =SUM(CG5:CI5)*100/12 -> 25 | CT5: =SUM(CJ5:CL5)*100/12 -> 41.666667 | CU5: =SUM(CM5:CT5)/8 -> 30.78125 | CV5: 2 | CW5: 0 | CX5: 2 | CY5: 0 | CZ5: 1 | DA5: 0 | DB5: 0 | DC5: 3 | DD5: 2 | DE5: 1 | DF5: 0 | DG5: 0 | DH5: 0 | DI5: 3 | DJ5: 0 | DK5: =SUM(CV5:DA5,DC5:DI5) -> 14 | DL5: 0 | DM5: 0 | DN5: 0 | DO5: 0 | DP5: 0 | DQ5: 0 | DR5: 1 | DS5: 2 | DT5: 1 | DU5: 0 | DV5: 1 | DW5: 0 | DX5: 0 | DY5: =SUM(DL5:DX5) -> 5 | DZ5: 0 | EA5: 0 | EB5: 0 | EC5: 0 | ED5: 2 | EE5: 0 | EF5: 2 | EG5: 0 | EH5: 0 | EI5: 0 | EJ5: 0 | EK5: 1 | EL5: 1 | EM5: 0 | EN5: 0 | EO5: 0 | EP5: 0 | EQ5: 1 | ER5: 1 | ES5: 1 | ET5: 0 | EU5: 0 | EV5: 0 | EW5: 0 | EX5: 1 | EY5: 0 | EZ5: 0 | FA5: 0 | FB5: 1 | FC5: 0 | FD5: 0 | FE5: 0 | FF5: 0 | FG5: =SUM(DZ5:FF5) -> 11 | FH5: 0 | FI5: 0 | FJ5: 0 | FK5: 0 | FL5: 0 | FM5: 0 | FN5: =SUM(FH5:FM5) -> 0 | FO5: =SUM(DK5,DY5,FG5,FN5) -> 30 | FP5: 13 | FQ5: 5 | FR5: 3 | FS5: 6 | FT5: 2 | FU5: 2 | FV5: 3 | FW5: 6 | FX5: =SUM(FQ5:FW5) -> 27 | FY5: 0 | FZ5: =IF($G5<=50,$FY5+0,IF(AND($G5<60,$G5>50),$FY5+1,IF(AND($G5<70,$G5>60),$FY5+2,IF(AND($G5<80,$G5>70),$FY5+3,IF(AND($G5<90,$G5>80),$FY5+4,IF($G5>=90,$FY5+5,"")))))) -> 1 | GA5: 1
A6: 5 | B6: 1 | C6: 1 | D6: 0 | E6: 20657 | F6: 44355 | G6: =DATEDIF(E6,F6,"M")/12 -> 64.833333 | H6: 50 | I6: =G6-H6 -> 14.833333 | J6: 0 | K6: 1 | L6: 8 | M6: 0 | N6: 2 | O6: 0 | P6: 2 | Q6: 4 | R6: 3 | S6: 1 | T6: 1 | U6: 0 | V6: 1 | W6: 1 | X6: 2 | Y6: 2 | Z6: 0 | AA6: 0 | AC6: 0 | AD6: 0 | AE6: 1 | AF6: 0 | AG6: 0 | AH6: 1 | AI6: =AJ6*ledd!$B$2+AK6*ledd!$B$3+AL6*ledd!$B$4+AM6*ledd!$B$5+AN6*ledd!$B$6+AO6*ledd!$B$7+AP6*ledd!$B$8+AQ6*ledd!$B$9+AR6*ledd!$B$10+AS6*ledd!$B$11+AT6*ledd!$B$12+AU6*ledd!$B$13+AV6*ledd!$B$14+AW6*ledd!$B$15+AX6*ledd!$B$16 -> 726.5 | AJ6: 250 | AK6: 0 | AL6: 0 | AM6: 0 | AN6: 0 | AO6: 8 | AP6: 0 | AQ6: 0 | AR6: 0 | AS6: 1 | AT6: 200 | AU6: 0 | AV6: 0 | AW6: 0 | AX6: 50 | AY6: 1 | AZ6: 2 | BA6: 0 | BB6: 0 | BC6: 0 | BD6: 0 | BE6: 0 | BF6: 0 | BG6: 0 | BH6: 0 | BI6: 0 | BJ6: 0 | BK6: 0 | BL6: 0 | BM6: 4 | BN6: 0 | BO6: 0 | BP6: 0 | BQ6: 0 | BR6: 0 | BS6: 0 | BT6: 0 | BU6: 0 | BV6: 0 | BW6: 0 | BX6: 0 | BY6: 0 | BZ6: 0 | CA6: 0 | CB6: 0 | CC6: 0 | CD6: 0 | CE6: 0 | CF6: 0 | CG6: 0 | CH6: 0 | CI6: 0 | CJ6: 0 | CK6: 0 | CL6: 0 | CM6: =(SUM(AZ6:BI6)*100/40) -> 5 | CN6: =SUM(BJ6:BO6)*100/24 -> 16.666667 | CO6: =SUM(BP6:BU6)*100/24 -> 0 | CP6: =SUM(BV6:BY6)*100/16 -> 0 | CQ6: =SUM(BZ6:CB6)*100/12 -> 0 | CR6: =SUM(CC6:CF6)*100/16 -> 0 | CS6: =SUM(CG6:CI6)*100/12 -> 0 | CT6: =SUM(CJ6:CL6)*100/12 -> 0 | CU6: =SUM(CM6:CT6)/8 -> 2.7083333 | CV6: 0 | CW6: 1 | CX6: 0 | CY6: 1 | CZ6: 0 | DA6: 0 | DB6: 0 | DC6: 0 | DD6: 0 | DE6: 0 | DF6: 0 | DG6: 3 | DH6: 0 | DI6: 0 | DJ6: 0 | DK6: =SUM(CV6:DA6,DC6:DI6) -> 5 | DL6: 1 | DM6: 0 | DN6: 1 | DO6: 0 | DP6: 0 | DQ6: 0 | DR6: 3 | DS6: 0 | DT6: 0 | DU6: 0 | DV6: 1 | DW6: 0 | DX6: 1 | DY6: =SUM(DL6:DX6) -> 7 | DZ6: 2 | EA6: 1 | EB6: 0 | EC6: 1 | ED6: 1 | EE6: 0 | EF6: 0 | EG6: 0 | EH6: 0 | EI6: 0 | EJ6: 0 | EK6: 1 | EL6: 0 | EM6: 0 | EN6: 0 | EO6: 0 | EP6: 0 | EQ6: 1 | ER6: 1 | ES6: 0 | ET6: 1 | EU6: 1 | EV6: 0 | EW6: 0 | EX6: 0 | EY6: 0 | EZ6: 0 | FA6: 0 | FB6: 0 | FC6: 0 | FD6: 0 | FE6: 0 | FF6: 0 | FG6: =SUM(DZ6:FF6) -> 10 | FH6: 0 | FI6: 1 | FJ6: 0 | FK6: 0 | FL6: 0 | FM6: 0 | FN6: =SUM(FH6:FM6) -> 1 | FO6: =SUM(DK6,DY6,FG6,FN6) -> 23 | FP6: 10 | FQ6: 3 | FR6: 3 | FS6: 6 | FT6: 3 | FU6: 2 | FV6: 5 | FW6: 6 | FX6: =SUM(FQ6:FW6) -> 28 | FY6: 0 | FZ6: =IF($G6<=50,$FY6+0,IF(AND($G6<60,$G6>50),$FY6+1,IF(AND($G6<70,$G6>60),$FY6+2,IF(AND($G6<80,$G6>70),$FY6+3,IF(AND($G6<90,$G6>80),$FY6+4,IF($G6>=90,$FY6+5,"")))))) -> 2 | GA6: 1
A7: 6 | B7: 1 | C7: 1 | D7: 0 | E7: 19424 | F7: 44355 | G7: =DATEDIF(E7,F7,"M")/12 -> 68.25 | H7: 52 | I7: =G7-H7 -> 16.25 | J7: 11 | K7: 3 | L7: 0 | M7: 0 | N7: 2 | O7: 2 | P7: 4 | Q7: 2 | R7: 1 | S7: 0 | T7: 0 | U7: 0 | V7: 1 | W7: 1 | X7: 0 | Y7: 0 | AA7: 1 | AB7: 3 | AC7: 0 | AD7: 0 | AE7: 0 | AF7: 0 | AG7: 0 | AH7: 0 | AI7: =AJ7*ledd!$B$2+AK7*ledd!$B$3+AL7*ledd!$B$4+AM7*ledd!$B$5+AN7*ledd!$B$6+AO7*ledd!$B$7+AP7*ledd!$B$8+AQ7*ledd!$B$9+AR7*ledd!$B$10+AS7*ledd!$B$11+AT7*ledd!$B$12+AU7*ledd!$B$13+AV7*ledd!$B$14+AW7*ledd!$B$15+AX7*ledd!$B$16 -> 716.5 | AJ7: 650 | AK7: 0 | AL7: 0 | AM7: 0 | AN7: 0 | AO7: 0 | AP7: 0 | AQ7: 0 | AR7: 0 | AS7: 0 | AT7: 0 | AU7: 0 | AV7: 0 | AW7: 50 | AX7: 50 | AY7: 3 | AZ7: 2 | BA7: 0 | BB7: 4 | BC7: 0 | BD7: 0 | BE7: 1 | BF7: 0 | BG7: 4 | BH7: 4 | BI7: 3 | BJ7: 0 | BK7: 0 | BL7: 0 | BM7: 3 | BN7: 0 | BO7: 0 | BP7: 0 | BQ7: 0 | BR7: 0 | BS7: 0 | BT7: 0 | BU7: 3 | BV7: 0 | BW7: 0 | BX7: 3 | BY7: 3 | BZ7: 3 | CA7: 2 | CB7: 0 | CC7: 3 | CD7: 3 | CE7: 3 | CF7: 0 | CG7: 1 | CH7: 0 | CI7: 0 | CJ7: 3 | CK7: 0 | CL7: 2 | CM7: =(SUM(AZ7:BI7)*100/40) -> 45 | CN7: =SUM(BJ7:BO7)*100/24 -> 12.5 | CO7: =SUM(BP7:BU7)*100/24 -> 12.5 | CP7: =SUM(BV7:BY7)*100/16 -> 37.5 | CQ7: =SUM(BZ7:CB7)*100/12 -> 41.666667 | CR7: =SUM(CC7:CF7)*100/16 -> 56.25 | CS7: =SUM(CG7:CI7)*100/12 -> 8.3333333 | CT7: =SUM(CJ7:CL7)*100/12 -> 41.666667 | CU7: =SUM(CM7:CT7)/8 -> 31.927083 | CV7: 2 | CW7: 0 | CX7: 0 | CY7: 2 | CZ7: 4 | DA7: 0 | DB7: 0 | DC7: 4 | DD7: 4 | DE7: 4 | DF7: 1 | DG7: 3 | DH7: 1 | DI7: 4 | DJ7: 0 | DK7: =SUM(CV7:DA7,DC7:DI7) -> 29 | DL7: 2 | DM7: 0 | DN7: 1 | DO7: 0 | DP7: 0 | DQ7: 0 | DR7: 2 | DS7: 4 | DT7: 1 | DU7: 1 | DV7: 0 | DW7: 2 | DX7: 4 | DY7: =SUM(DL7:DX7) -> 17 | DZ7: 1 | EA7: 2 | EB7: 3 | EC7: 2 | ED7: 2 | EE7: 2 | EF7: 4 | EG7: 1 | EH7: 2 | EI7: 1 | EJ7: 1 | EK7: 3 | EL7: 3 | EM7: 2 | EN7: 4 | EO7: 2 | EP7: 4 | EQ7: 2 | ER7: 2 | ES7: 2 | ET7: 2 | EU7: 2 | EV7: 2 | EW7: 1 | EX7: 1 | EY7: 1 | EZ7: 1 | FA7: 0 | FB7: 0 | FC7: 0 | FD7: 0 | FE7: 0 | FF7: 0 | FG7: =SUM(DZ7:FF7) -> 55 | FH7: 2 | FI7: 3 | FJ7: 3 | FK7: 4 | FL7: 1 | FM7: 1 | FN7: =SUM(FH7:FM7) -> 14 | FO7: =SUM(DK7,DY7,FG7,FN7) -> 115 | FP7: 7 | FQ7: 1 | FR7: 3 | FS7: 3 | FT7: 3 | FU7: 2 | FV7: 3 | FW7: 6 | FX7: =SUM(FQ7:FW7) -> 21 | FY7: 3 | FZ7: =IF($G7<=50,$FY7+0,IF(AND($G7<60,$G7>50),$FY7+1,IF(AND($G7<70,$G7>60),$FY7+2,IF(AND($G7<80,$G7>70),$FY7+3,IF(AND($G7<90,$G7>80),$FY7+4,IF($G7>=90,$FY7+5,"")))))) -> 5 | GA7: 1
A8: 7 | B8: 1 | C8: 1 | D8: 1 | E8: 29402 | F8: 44356 | G8: =DATEDIF(E8,F8,"M")/12 -> 40.916667 | H8: 34 | I8: =G8-H8 -> 6.9166667 | J8: 0 | K8: 1 | L8: 0 | M8: 0 | N8: 2 | O8: 0 | P8: 1 | Q8: 4 | R8: 3 | S8: 1 | T8: 1 | U8: 1 | V8: 1 | W8: 1 | X8: 2 | Y8: 2 | Z8: 0 | AA8: 1 | AB8: 0 | AC8: 0 | AD8: 0 | AE8: 0 | AF8: 0 | AG8: 0 | AH8: 0 | AI8: =AJ8*ledd!$B$2+AK8*ledd!$B$3+AL8*ledd!$B$4+AM8*ledd!$B$5+AN8*ledd!$B$6+AO8*ledd!$B$7+AP8*ledd!$B$8+AQ8*ledd!$B$9+AR8*ledd!$B$10+AS8*ledd!$B$11+AT8*ledd!$B$12+AU8*ledd!$B$13+AV8*ledd!$B$14+AW8*ledd!$B$15+AX8*ledd!$B$16 -> 751.5 | AJ8: 400 | AK8: 100 | AL8: 0 | AM8: 0 | AN8: 0 | AO8: 8 | AP8: 0 | AQ8: 0 | AR8: 0 | AS8: 0 | AT8: 0 | AU8: 0 | AV8: 0 | AW8: 100 | AX8: 50 | AY8: 1 | AZ8: 3 | BA8: 2 | BB8: 0 | BC8: 0 | BD8: 0 | BE8: 3 | BF8: 1 | BG8: 0 | BH8: 0 | BI8: 3 | BJ8: 2 | BK8: 1 | BL8: 1 | BM8: 3 | BN8: 1 | BO8: 1 | BP8: 0 | BQ8: 0 | BR8: 0 | BS8: 0 | BT8: 0 | BU8: 1 | BV8: 1 | BW8: 0 | BX8: 0 | BY8: 1 | BZ8: 0 | CA8: 0 | CB8: 0 | CC8: 1 | CD8: 2 | CE8: 0 | CF8: 0 | CG8: 1 | CH8: 1 | CI8: 0 | CJ8: 3 | CK8: 3 | CL8: 3 | CM8: =(SUM(AZ8:BI8)*100/40) -> 30 | CN8: =SUM(BJ8:BO8)*100/24 -> 37.5 | CO8: =SUM(BP8:BU8)*100/24 -> 4.1666667 | CP8: =SUM(BV8:BY8)*100/16 -> 12.5 | CQ8: =SUM(BZ8:CB8)*100/12 -> 0 | CR8: =SUM(CC8:CF8)*100/16 -> 18.75 | CS8: =SUM(CG8:CI8)*100/12 -> 16.666667 | CT8: =SUM(CJ8:CL8)*100/12 -> 75 | CU8: =SUM(CM8:CT8)/8 -> 24.322917 | CV8: 0 | CW8: 0 | CX8: 0 | CY8: 0 | CZ8: 0 | DA8: 3 | DB8: 0 | DC8: 3 | DD8: 0 | DE8: 4 | DF8: 0 | DG8: 0 | DH8: 0 | DI8: 3 | DJ8: 0 | DK8: =SUM(CV8:DA8,DC8:DI8) -> 13 | DL8: 0 | DM8: 0 | DN8: 0 | DO8: 1 | DP8: 3 | DQ8: 0 | DR8: 2 | DS8: 3 | DT8: 1 | DU8: 0 | DV8: 1 | DW8: 0 | DX8: 0 | DY8: =SUM(DL8:DX8) -> 11 | DZ8: 0 | EA8: 1 | EB8: 1 | EC8: 1 | ED8: 1 | EE8: 0 | EF8: 0 | EG8: 0 | EH8: 0 | EI8: 1 | EJ8: 2 | EK8: 2 | EL8: 3 | EM8: 0 | EN8: 0 | EO8: 0 | EP8: 0 | EQ8: 0 | ER8: 0 | ES8: 0 | ET8: 0 | EU8: 0 | EV8: 1 | EW8: 0 | EX8: 0 | EY8: 0 | EZ8: 0 | FA8: 0 | FB8: 0 | FC8: 0 | FD8: 0 | FE8: 0 | FF8: 0 | FG8: =SUM(DZ8:FF8) -> 13 | FH8: 2 | FI8: 4 | FJ8: 1 | FK8: 3 | FL8: 1 | FM8: 1 | FN8: =SUM(FH8:FM8) -> 12 | FO8: =SUM(DK8,DY8,FG8,FN8) -> 49 | FP8: 11 | FQ8: 5 | FR8: 3 | FS8: 6 | FT8: 3 | FU8: 2 | FV8: 3 | FW8: 6 | FX8: =SUM(FQ8:FW8) -> 28 | FY8: 0 | FZ8: =IF($G8<=50,$FY8+0,IF(AND($G8<60,$G8>50),$FY8+1,IF(AND($G8<70,$G8>60),$FY8+2,IF(AND($G8<80,$G8>70),$FY8+3,IF(AND($G8<90,$G8>80),$FY8+4,IF($G8>=90,$FY8+5,"")))))) -> 0 | GA8: 1
A9: 8 | B9: 1 | C9: 1 | D9: 1 | E9: 17670 | F9: 44361 | G9: =DATEDIF(E9,F9,"M")/12 -> 73 | H9: 56 | I9: =G9-H9 -> 17 | J9: 0 | K9: 0 | L9: 1 | M9: 0 | N9: 2 | O9: 0 | P9: 4 | Q9: 3 | R9: 2 | S9: 1 | T9: 1 | U9: 0 | V9: 1 | W9: 1 | X9: 0 | Y9: 0 | AA9: 0 | AC9: 0 | AD9: 0 | AE9: 0 | AF9: 0 | AG9: 0 | AH9: 2 | AI9: =AJ9*ledd!$B$2+AK9*ledd!$B$3+AL9*ledd!$B$4+AM9*ledd!$B$5+AN9*ledd!$B$6+AO9*ledd!$B$7+AP9*ledd!$B$8+AQ9*ledd!$B$9+AR9*ledd!$B$10+AS9*ledd!$B$11+AT9*ledd!$B$12+AU9*ledd!$B$13+AV9*ledd!$B$14+AW9*ledd!$B$15+AX9*ledd!$B$16 -> 920 | AJ9: 400 | AK9: 0 | AL9: 0 | AM9: 0 | AN9: 0 | AO9: 0 | AP9: 14 | AQ9: 0 | AR9: 0 | AS9: 1 | AT9: 0 | AU9: 0 | AV9: 0 | AW9: 0 | AX9: 0 | AY9: 5 | AZ9: 0 | BA9: 0 | BB9: 0 | BC9: 0 | BD9: 0 | BE9: 0 | BF9: 0 | BG9: 0 | BH9: 0 | BI9: 1 | BJ9: 0 | BK9: 1 | BL9: 2 | BM9: 1 | BN9: 0 | BO9: 0 | BP9: 0 | BQ9: 0 | BR9: 0 | BS9: 0 | BT9: 0 | BU9: 0 | BV9: 0 | BW9: 0 | BX9: 0 | BY9: 0 | BZ9: 0 | CA9: 0 | CB9: 0 | CC9: 0 | CD9: 0 | CE9: 0 | CF9: 0 | CG9: 1 | CH9: 0 | CI9: 0 | CJ9: 0 | CK9: 0 | CL9: 0 | CM9: =(SUM(AZ9:BI9)*100/40) -> 2.5 | CN9: =SUM(BJ9:BO9)*100/24 -> 16.666667 | CO9: =SUM(BP9:BU9)*100/24 -> 0 | CP9: =SUM(BV9:BY9)*100/16 -> 0 | CQ9: =SUM(BZ9:CB9)*100/12 -> 0 | CR9: =SUM(CC9:CF9)*100/16 -> 0 | CS9: =SUM(CG9:CI9)*100/12 -> 8.3333333 | CT9: =SUM(CJ9:CL9)*100/12 -> 0 | CU9: =SUM(CM9:CT9)/8 -> 3.4375 | CV9: 0 | CW9: 0 | CX9: 0 | CY9: 0 | CZ9: 0 | DA9: 0 | DB9: 0 | DC9: 0 | DD9: 1 | DE9: 0 | DF9: 0 | DG9: 0 | DH9: 0 | DI9: 0 | DJ9: 0 | DK9: =SUM(CV9:DA9,DC9:DI9) -> 1 | DL9: 1 | DM9: 1 | DN9: 0 | DO9: 0 | DP9: 2 | DQ9: 0 | DR9: 1 | DS9: 0 | DT9: 2 | DU9: 0 | DV9: 0 | DW9: 0 | DX9: 2 | DY9: =SUM(DL9:DX9) -> 9 | DZ9: 1 | EA9: 1 | EB9: 0 | EC9: 0 | ED9: 0 | EE9: 0 | EF9: 0 | EG9: 0 | EH9: 0 | EI9: 0 | EJ9: 0 | EK9: 0 | EL9: 0 | EM9: 0 | EN9: 0 | EO9: 0 | EP9: 0 | EQ9: 0 | ER9: 0 | ES9: 0 | ET9: 0 | EU9: 1 | EV9: 0 | EW9: 0 | EX9: 0 | EY9: 0 | EZ9: 0 | FA9: 0 | FB9: 0 | FC9: 0 | FD9: 0 | FE9: 0 | FF9: 0 | FG9: =SUM(DZ9:FF9) -> 3 | FH9: 0 | FI9: 0 | FJ9: 0 | FK9: 0 | FL9: 0 | FM9: 0 | FN9: =SUM(FH9:FM9) -> 0 | FO9: =SUM(DK9,DY9,FG9,FN9) -> 13 | FP9: 3 | FQ9: 3 | FR9: 3 | FS9: 4 | FT9: 3 | FU9: 1 | FV9: 3 | FW9: 6 | FX9: =SUM(FQ9:FW9) -> 23 | FY9: 2 | FZ9: =IF($G9<=50,$FY9+0,IF(AND($G9<60,$G9>50),$FY9+1,IF(AND($G9<70,$G9>60),$FY9+2,IF(AND($G9<80,$G9>70),$FY9+3,IF(AND($G9<90,$G9>80),$FY9+4,IF($G9>=90,$FY9+5,"")))))) -> 5 | GA9: 0
A10: 9 | B10: 1 | C10: 1 | D10: 1 | E10: 19453 | F10: 44357 | G10: =DATEDIF(E10,F10,"M")/12 -> 68.166667 | H10: 62 | I10: =G10-H10 -> 6.1666667 | J10: 0 | K10: 1 | L10: 0 | M10: 0 | N10: 2 | O10: 1 | P10: 1 | Q10: 1 | R10: 1 | S10: 0 | T10: 0 | U10: 0 | V10: 0 | W10: 1 | X10: 1 | Y10: 1 | Z10: 0 | AA10: 1 | AB10: 0 | AC10: 0 | AD10: 6 | AE10: 0 | AF10: 0 | AG10: 0 | AH10: 0 | AI10: =AJ10*ledd!$B$2+AK10*ledd!$B$3+AL10*ledd!$B$4+AM10*ledd!$B$5+AN10*ledd!$B$6+AO10*ledd!$B$7+AP10*ledd!$B$8+AQ10*ledd!$B$9+AR10*ledd!$B$10+AS10*ledd!$B$11+AT10*ledd!$B$12+AU10*ledd!$B$13+AV10*ledd!$B$14+AW10*ledd!$B$15+AX10*ledd!$B$16 -> 452 | AJ10: 400 | AK10: 0 | AL10: 0 | AM10: 0 | AN10: 0.52 | AO10: 0 | AP10: 0 | AQ10: 0 | AR10: 0 | AS10: 0 | AT10: 0 | AU10: 0 | AV10: 0 | AW10: 0 | AX10: 0 | AY10: 3 | AZ10: 2 | BA10: 2 | BB10: 2 | BC10: 2 | BD10: 1 | BE10: 2 | BF10: 1 | BG10: 1 | BH10: 2 | BI10: 2 | BJ10: 0 | BK10: 0 | BL10: 0 | BM10: 2 | BN10: 0 | BO10: 1 | BP10: 1 | BQ10: 1 | BR10: 1 | BS10: 0 | BT10: 2 | BU10: 2 | BV10: 0 | BW10: 1 | BX10: 1 | BY10: 1 | BZ10: 1 | CA10: 1 | CB10: 1 | CC10: 1 | CD10: 1 | CE10: 2 | CF10: 2 | CG10: 1 | CH10: 2 | CI10: 1 | CJ10: 2 | CK10: 2 | CL10: 2 | CM10: =(SUM(AZ10:BI10)*100/40) -> 42.5 | CN10: =SUM(BJ10:BO10)*100/24 -> 12.5 | CO10: =SUM(BP10:BU10)*100/24 -> 29.166667 | CP10: =SUM(BV10:BY10)*100/16 -> 18.75 | CQ10: =SUM(BZ10:CB10)*100/12 -> 25 | CR10: =SUM(CC10:CF10)*100/16 -> 37.5 | CS10: =SUM(CG10:CI10)*100/12 -> 33.333333 | CT10: =SUM(CJ10:CL10)*100/12 -> 50 | CU10: =SUM(CM10:CT10)/8 -> 31.09375 | CV10: 0 | CW10: 0 | CX10: 1 | CY10: 0 | CZ10: 0 | DA10: 0 | DB10: 0 | DC10: 0 | DD10: 0 | DE10: 0 | DF10: 0 | DG10: 0 | DH10: 0 | DI10: 0 | DJ10: 0 | DK10: =SUM(CV10:DA10,DC10:DI10) -> 1 | DL10: 1 | DM10: 0 | DN10: 0 | DO10: 0 | DP10: 0 | DQ10: 1 | DR10: 2 | DS10: 1 | DT10: 0 | DU10: 1 | DV10: 0 | DW10: 1 | DX10: 1 | DY10: =SUM(DL10:DX10) -> 8 | DZ10: 2 | EA10: 3 | EB10: 3 | EC10: 2 | ED10: 2 | EE10: 3 | EF10: 2 | EG10: 1 | EH10: 2 | EI10: 1 | EJ10: 1 | EK10: 1 | EL10: 1 | EM10: 1 | EN10: 2 | EO10: 0 | EP10: 0 | EQ10: 0 | ER10: 0 | ES10: 0 | ET10: 0 | EU10: 0 | EV10: 2 | EW10: 0 | EX10: 0 | EY10: 0 | EZ10: 0 | FA10: 0 | FB10: 0 | FC10: 2 | FD10: 0 | FE10: 0 | FF10: 1 | FG10: =SUM(DZ10:FF10) -> 32 | FH10: 1 | FI10: 1 | FJ10: 0 | FK10: 0 | FL10: 0 | FM10: 0 | FN10: =SUM(FH10:FM10) -> 2 | FO10: =SUM(DK10,DY10,FG10,FN10) -> 43 | FP10: 5 | FQ10: 3 | FR10: 3 | FS10: 5 | FT10: 1 | FU10: 1 | FV10: 0 | FW10: 6 | FX10: =SUM(FQ10:FW10) -> 19 | FY10: 0 | FZ10: =IF($G10<=50,$FY10+0,IF(AND($G10<60,$G10>50),$FY10+1,IF(AND($G10<70,$G10>60),$FY10+2,IF(AND($G10<80,$G10>70),$FY10+3,IF(AND($G10<90,$G10>80),$FY10+4,IF($G10>=90,$FY10+5,"")))))) -> 2 | GA10: 1
A11: 10 | B11: 1 | C11: 1 | D11: 1 | E11: 18226 | F11: 44363 | G11: =DATEDIF(E11,F11,"M")/12 -> 71.5 | H11: 65 | I11: =G11-H11 -> 6.5 | J11: 0 | K11: 1 | L11: 0 | M11: 0 | N11: 2 | O11: 0 | P11: 3 | Q11: 2 | R11: 2 | S11: 1 | T11: 0 | U11: 0 | V11: 1 | W11: 1 | X11: 3 | Y11: 3 | Z11: 0 | AA11: 2 | AB11: 0 | AC11: 0 | AD11: 5 | AE11: 1 | AF11: 0 | AG11: 0 | AH11: 1 | AI11: =AJ11*ledd!$B$2+AK11*ledd!$B$3+AL11*ledd!$B$4+AM11*ledd!$B$5+AN11*ledd!$B$6+AO11*ledd!$B$7+AP11*ledd!$B$8+AQ11*ledd!$B$9+AR11*ledd!$B$10+AS11*ledd!$B$11+AT11*ledd!$B$12+AU11*ledd!$B$13+AV11*ledd!$B$14+AW11*ledd!$B$15+AX11*ledd!$B$16 -> 550 | AJ11: 400 | AK11: 0 | AL11: 0 | AM11: 0 | AN11: 0 | AO11: 0 | AP11: 0 | AQ11: 0 | AR11: 0 | AS11: 0 | AT11: 0 | AU11: 0 | AV11: 150 | AW11: 0 | AX11: 0 | AY11: 3 | AZ11: 0 | BA11: 0 | BB11: 0 | BC11: 0 | BD11: 0 | BE11: 2 | BF11: 1 | BG11: 0 | BH11: 0 | BI11: 2 | BJ11: 0 | BK11: 0 | BL11: 0 | BM11: 3 | BN11: 0 | BO11: 2 | BP11: 0 | BQ11: 0 | BR11: 0 | BS11: 0 | BT11: 0 | BU11: 0 | BV11: 1 | BW11: 0 | BX11: 0 | BY11: 0 | BZ11: 0 | CA11: 0 | CB11: 0 | CC11: 1 | CD11: 2 | CE11: 2 | CF11: 0 | CG11: 0 | CH11: 0 | CI11: 0 | CJ11: 1 | CK11: 0 | CL11: 0 | CM11: =(SUM(AZ11:BI11)*100/40) -> 12.5 | CN11: =SUM(BJ11:BO11)*100/24 -> 20.833333 | CO11: =SUM(BP11:BU11)*100/24 -> 0 | CP11: =SUM(BV11:BY11)*100/16 -> 6.25 | CQ11: =SUM(BZ11:CB11)*100/12 -> 0 | CR11: =SUM(CC11:CF11)*100/16 -> 31.25 | CS11: =SUM(CG11:CI11)*100/12 -> 0 | CT11: =SUM(CJ11:CL11)*100/12 -> 8.3333333 | CU11: =SUM(CM11:CT11)/8 -> 9.8958333 | CV11: 0 | CW11: 0 | CX11: 0 | CY11: 0 | CZ11: 0 | DA11: 0 | DB11: 0 | DC11: 2 | DD11: 0 | DE11: 0 | DF11: 0 | DG11: 0 | DH11: 0 | DI11: 0 | DJ11: 0 | DK11: =SUM(CV11:DA11,DC11:DI11) -> 2 | DL11: 0 | DM11: 1 | DN11: 0 | DO11: 0 | DP11: 0 | DQ11: 0 | DR11: 2 | DS11: 0 | DT11: 0 | DU11: 2 | DV11: 0 | DW11: 0 | DX11: 1 | DY11: =SUM(DL11:DX11) -> 6 | DZ11: 0 | EA11: 0 | EB11: 0 | EC11: 0 | ED11: 0 | EE11: 0 | EF11: 0 | EG11: 0 | EH11: 0 | EI11: 0 | EJ11: 0 | EK11: 0 | EL11: 0 | EM11: 0 | EN11: 0 | EO11: 0 | EP11: 0 | EQ11: 0 | ER11: 0 | ES11: 1 | ET11: 0 | EU11: 0 | EV11: 0 | EW11: 0 | EX11: 2 | EY11: 0 | EZ11: 2 | FA11: 0 | FB11: 2 | FC11: 0 | FD11: 0 | FE11: 0 | FF11: 3 | FG11: =SUM(DZ11:FF11) -> 10 | FH11: 0 | FI11: 0 | FJ11: 0 | FK11: 0 | FL11: 0 | FM11: 0 | FN11: =SUM(FH11:FM11) -> 0 | FO11: =SUM(DK11,DY11,FG11,FN11) -> 18 | FP11: 4 | FQ11: 5 | FR11: 3 | FS11: 6 | FT11: 3 | FU11: 2 | FV11: 2 | FW11: 6 | FX11: =SUM(FQ11:FW11) -> 27 | FY11: 0 | FZ11: =IF($G11<=50,$FY11+0,IF(AND($G11<60,$G11>50),$FY11+1,IF(AND($G11<70,$G11>60),$FY11+2,IF(AND($G11<80,$G11>70),$FY11+3,IF(AND($G11<90,$G11>80),$FY11+4,IF($G11>=90,$FY11+5,"")))))) -> 3 | GA11: 0
A12: 11 | B12: 1 | C12: 1 | D12: 1 | E12: 20170 | F12: 44368 | G12: =DATEDIF(E12,F12,"M")/12 -> 66.166667 | H12: 42 | I12: =G12-H12 -> 24.166667 | J12: 0 | K12: 1 | L12: 0 | M12: 0 | N12: 2 | O12: 2 | P12: 1 | Q12: 3 | R12: 2 | S12: 1 | T12: 1 | U12: 0 | V12: 1 | W12: 1 | X12: 2 | Y12: 1 | Z12: 0 | AA12: 0 | AC12: 0 | AD12: 3 | AE12: 0 | AF12: 0 | AG12: 0 | AH12: 0 | AI12: =AJ12*ledd!$B$2+AK12*ledd!$B$3+AL12*ledd!$B$4+AM12*ledd!$B$5+AN12*ledd!$B$6+AO12*ledd!$B$7+AP12*ledd!$B$8+AQ12*ledd!$B$9+AR12*ledd!$B$10+AS12*ledd!$B$11+AT12*ledd!$B$12+AU12*ledd!$B$13+AV12*ledd!$B$14+AW12*ledd!$B$15+AX12*ledd!$B$16 -> 819 | AJ12: 75 | AK12: 200 | AL12: 800 | AM12: 0 | AN12: 0 | AO12: 0 | AP12: 6 | AQ12: 0 | AR12: 0 | AS12: 0 | AT12: 50 | AU12: 0 | AV12: 0 | AW12: 100 | AX12: 0 | AY12: 5 | AZ12: 3 | BA12: 0 | BB12: 2 | BC12: 4 | BD12: 0 | BE12: 3 | BF12: 0 | BG12: 3 | BH12: 0 | BI12: 3 | BJ12: 0 | BK12: 3 | BL12: 2 | BM12: 4 | BN12: 1 | BO12: 0 | BP12: 1 | BQ12: 0 | BR12: 1 | BS12: 1 | BT12: 0 | BU12: 0 | BV12: 0 | BW12: 3 | BX12: 0 | BY12: 0 | BZ12: 0 | CA12: 0 | CB12: 0 | CC12: 0 | CD12: 3 | CE12: 2 | CF12: 4 | CG12: 3 | CH12: 2 | CI12: 0 | CJ12: 2 | CK12: 0 | CL12: 0 | CM12: =(SUM(AZ12:BI12)*100/40) -> 45 | CN12: =SUM(BJ12:BO12)*100/24 -> 41.666667 | CO12: =SUM(BP12:BU12)*100/24 -> 12.5 | CP12: =SUM(BV12:BY12)*100/16 -> 18.75 | CQ12: =SUM(BZ12:CB12)*100/12 -> 0 | CR12: =SUM(CC12:CF12)*100/16 -> 56.25 | CS12: =SUM(CG12:CI12)*100/12 -> 41.666667 | CT12: =SUM(CJ12:CL12)*100/12 -> 16.666667 | CU12: =SUM(CM12:CT12)/8 -> 29.0625 | CV12: 2 | CW12: 2 | CX12: 0 | CY12: 0 | CZ12: 0 | DA12: 0 | DB12: 0 | DC12: 2 | DD12: 0 | DE12: 0 | DF12: 0 | DG12: 3 | DH12: 1 | DI12: 0 | DJ12: 0 | DK12: =SUM(CV12:DA12,DC12:DI12) -> 10 | DL12: 2 | DM12: 3 | DN12: 1 | DO12: 1 | DP12: 2 | DQ12: 0 | DR12: 4 | DS12: 3 | DT12: 1 | DU12: 0 | DV12: 0 | DW12: 2 | DX12: 1 | DY12: =SUM(DL12:DX12) -> 20 | DZ12: 2 | EA12: 1 | EB12: 0 | EC12: 0 | ED12: 0 | EE12: 0 | EF12: 0 | EG12: 0 | EH12: 0 | EI12: 1 | EJ12: 0 | EK12: 0 | EL12: 0 | EM12: 0 | EN12: 0 | EO12: 0 | EP12: 0 | EQ12: 0 | ER12: 2 | ES12: 1 | ET12: 0 | EU12: 2 | EV12: 1 | EW12: 0 | EX12: 0 | EY12: 0 | EZ12: 0 | FA12: 0 | FB12: 0 | FC12: 0 | FD12: 0 | FE12: 0 | FF12: 0 | FG12: =SUM(DZ12:FF12) -> 10 | FH12: 0 | FI12: 0 | FJ12: 0 | FK12: 0 | FL12: 0 | FM12: 0 | FN12: =SUM(FH12:FM12) -> 0 | FO12: =SUM(DK12,DY12,FG12,FN12) -> 40 | FP12: 6 | FQ12: 5 | FR12: 3 | FS12: 6 | FT12: 3 | FU12: 2 | FV12: 4 | FW12: 6 | FX12: =SUM(FQ12:FW12) -> 29 | FY12: 1 | FZ12: =IF($G12<=50,$FY12+0,IF(AND($G12<60,$G12>50),$FY12+1,IF(AND($G12<70,$G12>60),$FY12+2,IF(AND($G12<80,$G12>70),$FY12+3,IF(AND($G12<90,$G12>80),$FY12+4,IF($G12>=90,$FY12+5,"")))))) -> 3 | GA12: 1
A13: 12 | B13: 1 | C13: 1 | D13: 1 | E13: 19219 | F13: 44370 | G13: =DATEDIF(E13,F13,"M")/12 -> 68.833333 | H13: 57 | I13: =G13-H13 -> 11.833333 | J13: 0 | K13: 1 | L13: 0 | M13: 0 | N13: 2 | O13: 0 | P13: 2 | Q13: 2 | R13: 1 | S13: 0 | T13: 0 | U13: 0 | V13: 1 | W13: 1 | X13: 2 | Y13: 2 | Z13: 0 | AA13: 0 | AC13: 1 | AD13: 1 | AE13: 0 | AF13: 0 | AG13: 0 | AH13: 0 | AI13: =AJ13*ledd!$B$2+AK13*ledd!$B$3+AL13*ledd!$B$4+AM13*ledd!$B$5+AN13*ledd!$B$6+AO13*ledd!$B$7+AP13*ledd!$B$8+AQ13*ledd!$B$9+AR13*ledd!$B$10+AS13*ledd!$B$11+AT13*ledd!$B$12+AU13*ledd!$B$13+AV13*ledd!$B$14+AW13*ledd!$B$15+AX13*ledd!$B$16 -> 350 | AJ13: 200 | AK13: 200 | AL13: 0 | AM13: 0 | AN13: 0 | AO13: 0 | AP13: 0 | AQ13: 0 | AR13: 0 | AS13: 0 | AT13: 0 | AU13: 0 | AV13: 0 | AW13: 0 | AX13: 0 | AY13: 5 | AZ13: 2 | BA13: 0 | BB13: 1 | BC13: 0 | BD13: 0 | BE13: 0 | BF13: 2 | BG13: 0 | BH13: 0 | BI13: 1 | BJ13: 0 | BK13: 0 | BL13: 0 | BM13: 3 | BN13: 0 | BO13: 0 | BP13: 0 | BQ13: 0 | BR13: 0 | BS13: 0 | BT13: 0 | BU13: 0 | BV13: 0 | BW13: 0 | BX13: 0 | BY13: 0 | BZ13: 0 | CA13: 0 | CB13: 0 | CC13: 0 | CD13: 2 | CE13: 0 | CF13: 2 | CG13: 0 | CH13: 0 | CI13: 0 | CJ13: 0 | CK13: 4 | CL13: 0 | CM13: =(SUM(AZ13:BI13)*100/40) -> 15 | CN13: =SUM(BJ13:BO13)*100/24 -> 12.5 | CO13: =SUM(BP13:BU13)*100/24 -> 0 | CP13: =SUM(BV13:BY13)*100/16 -> 0 | CQ13: =SUM(BZ13:CB13)*100/12 -> 0 | CR13: =SUM(CC13:CF13)*100/16 -> 25 | CS13: =SUM(CG13:CI13)*100/12 -> 0 | CT13: =SUM(CJ13:CL13)*100/12 -> 33.333333 | CU13: =SUM(CM13:CT13)/8 -> 10.729167 | CV13: 0 | CW13: 0 | CX13: 0 | CY13: 0 | CZ13: 0 | DA13: 0 | DB13: 0 | DC13: 0 | DD13: 0 | DE13: 2 | DF13: 0 | DG13: 0 | DH13: 1 | DI13: 1 | DJ13: 0 | DK13: =SUM(CV13:DA13,DC13:DI13) -> 4 | DL13: 0 | DM13: 0 | DN13: 0 | DO13: 1 | DP13: 0 | DQ13: 0 | DR13: 3 | DS13: 3 | DT13: 0 | DU13: 1 | DV13: 0 | DW13: 0 | DX13: 1 | DY13: =SUM(DL13:DX13) -> 9 | DZ13: 0 | EA13: 1 | EB13: 0 | EC13: 1 | ED13: 1 | EE13: 1 | EF13: 1 | EG13: 1 | EH13: 1 | EI13: 1 | EJ13: 1 | EK13: 1 | EL13: 1 | EM13: 2 | EN13: 1 | EO13: 2 | EP13: 1 | EQ13: 0 | ER13: 1 | ES13: 1 | ET13: 1 | EU13: 1 | EV13: 2 | EW13: 0 | EX13: 0 | EY13: 0 | EZ13: 0 | FA13: 0 | FB13: 0 | FC13: 0 | FD13: 0 | FE13: 0 | FF13: 0 | FG13: =SUM(DZ13:FF13) -> 23 | FH13: 1 | FI13: 1 | FJ13: 1 | FK13: 1 | FL13: 1 | FM13: 4 | FN13: =SUM(FH13:FM13) -> 9 | FO13: =SUM(DK13,DY13,FG13,FN13) -> 45 | FP13: 6 | FQ13: 3 | FR13: 3 | FS13: 6 | FT13: 2 | FU13: 2 | FV13: 4 | FW13: 6 | FX13: =SUM(FQ13:FW13) -> 26 | FY13: 0 | FZ13: =IF($G13<=50,$FY13+0,IF(AND($G13<60,$G13>50),$FY13+1,IF(AND($G13<70,$G13>60),$FY13+2,IF(AND($G13<80,$G13>70),$FY13+3,IF(AND($G13<90,$G13>80),$FY13+4,IF($G13>=90,$FY13+5,"")))))) -> 2 | GA13: 1
A14: 13 | B14: 1 | C14: 1 | D14: 0 | E14: 22915 | F14: 44371 | G14: =DATEDIF(E14,F14,"M")/12 -> 58.666667 | H14: 50 | I14: =G14-H14 -> 8.6666667 | J14: 0 | K14: 1 | L14: 2 | M14: 0 | N14: 2 | O14: 1 | P14: 1 | Q14: 4 | R14: 3 | S14: 0 | T14: 0 | U14: 0 | V14: 1 | W14: 1 | X14: 2 | Y14: 2 | Z14: 0 | AA14: 0 | AC14: 0 | AD14: 0 | AE14: 1 | AF14: 0 | AG14: 0 | AH14: 0 | AI14: =AJ14*ledd!$B$2+AK14*ledd!$B$3+AL14*ledd!$B$4+AM14*ledd!$B$5+AN14*ledd!$B$6+AO14*ledd!$B$7+AP14*ledd!$B$8+AQ14*ledd!$B$9+AR14*ledd!$B$10+AS14*ledd!$B$11+AT14*ledd!$B$12+AU14*ledd!$B$13+AV14*ledd!$B$14+AW14*ledd!$B$15+AX14*ledd!$B$16 -> 1341.5 | AJ14: 475 | AK14: 200 | AL14: 0 | AM14: 0 | AN14: 0 | AO14: 20 | AP14: 0 | AQ14: 0 | AR14: 0 | AS14: 0 | AT14: 200 | AU14: 0 | AV14: 0 | AW14: 100 | AX14: 50 | AY14: 6 | AZ14: 3 | BA14: 3 | BB14: 4 | BC14: 4 | BD14: 2 | BE14: 3 | BF14: 3 | BG14: 3 | BH14: 3 | BI14: 3 | BJ14: 3 | BK14: 3 | BL14: 3 | BM14: 3 | BN14: 3 | BO14: 0 | BP14: 3 | BQ14: 0 | BR14: 2 | BS14: 2 | BT14: 2 | BU14: 3 | BV14: 0 | BW14: 0 | BX14: 0 | BY14: 0 | BZ14: 0 | CA14: 0 | CB14: 0 | CC14: 0 | CD14: 2 | CE14: 2 | CF14: 3 | CG14: 0 | CH14: 0 | CI14: 0 | CJ14: 4 | CK14: 4 | CL14: 4 | CM14: =(SUM(AZ14:BI14)*100/40) -> 77.5 | CN14: =SUM(BJ14:BO14)*100/24 -> 62.5 | CO14: =SUM(BP14:BU14)*100/24 -> 50 | CP14: =SUM(BV14:BY14)*100/16 -> 0 | CQ14: =SUM(BZ14:CB14)*100/12 -> 0 | CR14: =SUM(CC14:CF14)*100/16 -> 43.75 | CS14: =SUM(CG14:CI14)*100/12 -> 0 | CT14: =SUM(CJ14:CL14)*100/12 -> 100 | CU14: =SUM(CM14:CT14)/8 -> 41.71875 | CV14: 0 | CW14: 1 | CX14: 0 | CY14: 0 | CZ14: 0 | DA14: 1 | DB14: 0 | DC14: 3 | DD14: 0 | DE14: 4 | DF14: 1 | DG14: 2 | DH14: 2 | DI14: 0 | DJ14: 0 | DK14: =SUM(CV14:DA14,DC14:DI14) -> 14 | DL14: 2 | DM14: 0 | DN14: 0 | DO14: 1 | DP14: 3 | DQ14: 3 | DR14: 3 | DS14: 3 | DT14: 3 | DU14: 0 | DV14: 3 | DW14: 3 | DX14: 3 | DY14: =SUM(DL14:DX14) -> 27 | DZ14: 1 | EA14: 0 | EB14: 0 | EC14: 0 | ED14: 0 | EE14: 0 | EF14: 0 | EG14: 0 | EH14: 0 | EI14: 0 | EJ14: 0 | EK14: 0 | EL14: 0 | EM14: 0 | EN14: 0 | EO14: 0 | EP14: 0 | EQ14: 0 | ER14: 3 | ES14: 1 | ET14: 1 | EU14: 3 | EV14: 0 | EW14: 0 | EX14: 0 | EY14: 0 | EZ14: 0 | FA14: 0 | FB14: 0 | FC14: 0 | FD14: 0 | FE14: 0 | FF14: 0 | FG14: =SUM(DZ14:FF14) -> 9 | FH14: 0 | FI14: 0 | FJ14: 2 | FK14: 0 | FL14: 0 | FM14: 4 | FN14: =SUM(FH14:FM14) -> 6 | FO14: =SUM(DK14,DY14,FG14,FN14) -> 56 | FP14: 9 | FQ14: 5 | FR14: 3 | FS14: 5 | FT14: 3 | FU14: 2 | FV14: 5 | FW14: 6 | FX14: =SUM(FQ14:FW14) -> 29 | FY14: 0 | FZ14: =IF($G14<=50,$FY14+0,IF(AND($G14<60,$G14>50),$FY14+1,IF(AND($G14<70,$G14>60),$FY14+2,IF(AND($G14<80,$G14>70),$FY14+3,IF(AND($G14<90,$G14>80),$FY14+4,IF($G14>=90,$FY14+5,"")))))) -> 1 | GA14: 1
A15: 14 | B15: 1 | C15: 1 | D15: 0 | E15: 18735 | F15: 44375 | G15: =DATEDIF(E15,F15,"M")/12 -> 70.166667 | H15: 53 | I15: =G15-H15 -> 17.166667 | J15: 0 | K15: 3 | L15: 8 | M15: 0 | N15: 2 | O15: 1 | P15: 2 | Q15: 1 | R15: 1 | S15: 1 | T15: 1 | U15: 0 | V15: 1 | W15: 1 | X15: 3 | Y15: 3 | Z15: 0 | AA15: 1 | AB15: 0 | AC15: 6 | AD15: 0 | AE15: 0 | AF15: 0 | AG15: 0 | AH15: 0 | AI15: =AJ15*ledd!$B$2+AK15*ledd!$B$3+AL15*ledd!$B$4+AM15*ledd!$B$5+AN15*ledd!$B$6+AO15*ledd!$B$7+AP15*ledd!$B$8+AQ15*ledd!$B$9+AR15*ledd!$B$10+AS15*ledd!$B$11+AT15*ledd!$B$12+AU15*ledd!$B$13+AV15*ledd!$B$14+AW15*ledd!$B$15+AX15*ledd!$B$16 -> 1355 | AJ15: 700 | AK15: 100 | AL15: 0 | AM15: 0 | AN15: 0 | AO15: 0 | AP15: 16 | AQ15: 0 | AR15: 0 | AS15: 1 | AT15: 0 | AU15: 0 | AV15: 0 | AW15: 0 | AX15: 0 | AY15: 5 | AZ15: 3 | BA15: 3 | BB15: 4 | BC15: 3 | BD15: 1 | BE15: 2 | BF15: 1 | BG15: 0 | BH15: 0 | BI15: 0 | BJ15: 1 | BK15: 2 | BL15: 1 | BM15: 1 | BN15: 0 | BO15: 1 | BP15: 1 | BQ15: 0 | BR15: 1 | BS15: 1 | BT15: 2 | BU15: 0 | BV15: 0 | BW15: 2 | BX15: 0 | BY15: 0 | BZ15: 0 | CA15: 0 | CB15: 0 | CC15: 0 | CD15: 0 | CE15: 0 | CF15: 1 | CG15: 0 | CH15: 0 | CI15: 0 | CJ15: 1 | CK15: 2 | CL15: 0 | CM15: =(SUM(AZ15:BI15)*100/40) -> 42.5 | CN15: =SUM(BJ15:BO15)*100/24 -> 25 | CO15: =SUM(BP15:BU15)*100/24 -> 20.833333 | CP15: =SUM(BV15:BY15)*100/16 -> 12.5 | CQ15: =SUM(BZ15:CB15)*100/12 -> 0 | CR15: =SUM(CC15:CF15)*100/16 -> 6.25 | CS15: =SUM(CG15:CI15)*100/12 -> 0 | CT15: =SUM(CJ15:CL15)*100/12 -> 25 | CU15: =SUM(CM15:CT15)/8 -> 16.510417 | CV15: 0 | CW15: 1 | CX15: 1 | CY15: 0 | CZ15: 0 | DA15: 2 | DB15: 0 | DC15: 4 | DD15: 0 | DE15: 0 | DF15: 0 | DG15: 0 | DH15: 0 | DI15: 1 | DJ15: 0 | DK15: =SUM(CV15:DA15,DC15:DI15) -> 9 | DL15: 0 | DM15: 1 | DN15: 0 | DO15: 0 | DP15: 1 | DQ15: 1 | DR15: 0 | DS15: 1 | DT15: 2 | DU15: 2 | DV15: 2 | DW15: 1 | DX15: 1 | DY15: =SUM(DL15:DX15) -> 12 | DZ15: 0 | EA15: 1 | EB15: 0 | EC15: 1 | ED15: 1 | EE15: 0 | EF15: 0 | EG15: 0 | EH15: 0 | EI15: 0 | EJ15: 0 | EK15: 0 | EL15: 0 | EM15: 0 | EN15: 1 | EO15: 0 | EP15: 0 | EQ15: 0 | ER15: 0 | ES15: 0 | ET15: 1 | EU15: 1 | EV15: 1 | EW15: 0 | EX15: 0 | EY15: 0 | EZ15: 0 | FA15: 0 | FB15: 0 | FC15: 0 | FD15: 0 | FE15: 0 | FF15: 0 | FG15: =SUM(DZ15:FF15) -> 7 | FH15: 0 | FI15: 0 | FJ15: 1 | FK15: 1 | FL15: 3 | FM15: 0 | FN15: =SUM(FH15:FM15) -> 5 | FO15: =SUM(DK15,DY15,FG15,FN15) -> 33 | FP15: 6 | FQ15: 3 | FR15: 3 | FS15: 6 | FT15: 3 | FU15: 2 | FV15: 4 | FW15: 6 | FX15: =SUM(FQ15:FW15) -> 27 | FY15: 0 | FZ15: =IF($G15<=50,$FY15+0,IF(AND($G15<60,$G15>50),$FY15+1,IF(AND($G15<70,$G15>60),$FY15+2,IF(AND($G15<80,$G15>70),$FY15+3,IF(AND($G15<90,$G15>80),$FY15+4,IF($G15>=90,$FY15+5,"")))))) -> 3 | GA15: 1
A16: 15 | B16: 1 | C16: 1 | D16: 0 | E16: 19966 | F16: 44379 | G16: =DATEDIF(E16,F16,"M")/12 -> 66.833333 | H16: 56 | I16: =G16-H16 -> 10.833333 | J16: 0 | K16: 5 | L16: 1 | M16: 3 | N16: 1 | O16: 2 | P16: 2 | Q16: 1 | R16: 0 | S16: 1 | T16: 1 | U16: 0 | V16: 1 | W16: 1 | X16: 2 | Y16: 2 | Z16: 5 | AA16: 0 | AC16: 3 | AD16: 3 | AE16: 1 | AF16: 1 | AG16: 0 | AH16: 1 | AI16: =AJ16*ledd!$B$2+AK16*ledd!$B$3+AL16*ledd!$B$4+AM16*ledd!$B$5+AN16*ledd!$B$6+AO16*ledd!$B$7+AP16*ledd!$B$8+AQ16*ledd!$B$9+AR16*ledd!$B$10+AS16*ledd!$B$11+AT16*ledd!$B$12+AU16*ledd!$B$13+AV16*ledd!$B$14+AW16*ledd!$B$15+AX16*ledd!$B$16 -> 391 | AJ16: 100 | AK16: 100 | AL16: 200 | AM16: 0 | AN16: 0 | AO16: 0 | AP16: 0 | AQ16: 0 | AR16: 0 | AS16: 0 | AT16: 0 | AU16: 0 | AV16: 150 | AW16: 0 | AX16: 0 | AY16: 7 | AZ16: 4 | BA16: 4 | BB16: 4 | BC16: 4 | BD16: 4 | BE16: 4 | BF16: 4 | BG16: 4 | BH16: 4 | BI16: 4 | BJ16: 3 | BK16: 4 | BL16: 4 | BM16: 4 | BN16: 4 | BO16: 1 | BP16: 3 | BQ16: 0 | BR16: 0 | BS16: 0 | BT16: 2 | BU16: 4 | BV16: 0 | BW16: 0 | BX16: 0 | BY16: 0 | BZ16: 0 | CA16: 0 | CB16: 0 | CC16: 0 | CD16: 1 | CE16: 2 | CF16: 3 | CG16: 0 | CH16: 0 | CI16: 0 | CJ16: 3 | CK16: 3 | CL16: 1 | CM16: =(SUM(AZ16:BI16)*100/40) -> 100 | CN16: =SUM(BJ16:BO16)*100/24 -> 83.333333 | CO16: =SUM(BP16:BU16)*100/24 -> 37.5 | CP16: =SUM(BV16:BY16)*100/16 -> 0 | CQ16: =SUM(BZ16:CB16)*100/12 -> 0 | CR16: =SUM(CC16:CF16)*100/16 -> 37.5 | CS16: =SUM(CG16:CI16)*100/12 -> 0 | CT16: =SUM(CJ16:CL16)*100/12 -> 58.333333 | CU16: =SUM(CM16:CT16)/8 -> 39.583333 | CV16: 1 | CW16: 0 | CX16: 1 | CY16: 0 | CZ16: 0 | DA16: 0 | DB16: 0 | DC16: 1 | DD16: 0 | DE16: 2 | DF16: 0 | DG16: 0 | DH16: 4 | DI16: 0 | DJ16: 0 | DK16: =SUM(CV16:DA16,DC16:DI16) -> 9 | DL16: 0 | DM16: 1 | DN16: 2 | DO16: 3 | DP16: 4 | DQ16: 4 | DR16: 4 | DS16: 4 | DT16: 4 | DU16: 0 | DV16: 4 | DW16: 4 | DX16: 4 | DY16: =SUM(DL16:DX16) -> 38 | DZ16: 0 | EA16: 2 | EB16: 3 | EC16: 4 | ED16: 3 | EE16: 0 | EF16: 0 | EG16: 0 | EH16: 0 | EI16: 0 | EJ16: 0 | EK16: 0 | EL16: 0 | EM16: 4 | EN16: 4 | EO16: 4 | EP16: 4 | EQ16: 4 | ER16: 4 | ES16: 4 | ET16: 4 | EU16: 4 | EV16: 4 | EW16: 0 | EX16: 0 | EY16: 0 | EZ16: 0 | FA16: 0 | FB16: 0 | FC16: 0 | FD16: 0 | FE16: 0 | FF16: 0 | FG16: =SUM(DZ16:FF16) -> 52 | FH16: 0 | FI16: 0 | FJ16: 1 | FK16: 4 | FL16: 1 | FM16: 4 | FN16: =SUM(FH16:FM16) -> 10 | FO16: =SUM(DK16,DY16,FG16,FN16) -> 109 | FP16: 9 | FQ16: 4 | FR16: 3 | FS16: 4 | FT16: 2 | FU16: 2 | FV16: 1 | FW16: 6 | FX16: =SUM(FQ16:FW16) -> 22 | FY16: 0 | FZ16: =IF($G16<=50,$FY16+0,IF(AND($G16<60,$G16>50),$FY16+1,IF(AND($G16<70,$G16>60),$FY16+2,IF(AND($G16<80,$G16>70),$FY16+3,IF(AND($G16<90,$G16>80),$FY16+4,IF($G16>=90,$FY16+5,"")))))) -> 2 | GA16: 1
A17: 16 | B17: 1 | C17: 1 | D17: 0 | E17: 19512 | F17: 44382 | G17: =DATEDIF(E17,F17,"M")/12 -> 68.083333 | H17: 43 | I17: =G17-H17 -> 25.083333 | J17: 0 | K17: 0 | L17: 8 | M17: 0 | N17: 2 | O17: 2 | P17: 0 | Q17: 4 | R17: 1 | S17: 1 | T17: 1 | U17: 0 | V17: 1 | W17: 1 | X17: 3 | Y17: 3 | Z17: 6 | AA17: 2 | AB17: 0 | AC17: 3 | AD17: 3 | AE17: 1 | AF17: 1 | AG17: 0 | AH17: 1 | AI17: =AJ17*ledd!$B$2+AK17*ledd!$B$3+AL17*ledd!$B$4+AM17*ledd!$B$5+AN17*ledd!$B$6+AO17*ledd!$B$7+AP17*ledd!$B$8+AQ17*ledd!$B$9+AR17*ledd!$B$10+AS17*ledd!$B$11+AT17*ledd!$B$12+AU17*ledd!$B$13+AV17*ledd!$B$14+AW17*ledd!$B$15+AX17*ledd!$B$16 -> 2208 | AJ17: 825 | AK17: 100 | AL17: 1600 | AM17: 0 | AN17: 0 | AO17: 0 | AP17: 16 | AQ17: 0 | AR17: 0 | AS17: 0 | AT17: 300 | AU17: 0 | AV17: 0 | AW17: 0 | AX17: 0 | AY17: 4 | AZ17: 2 | BA17: 3 | BB17: 3 | BC17: 3 | BD17: 1 | BE17: 3 | BF17: 3 | BG17: 0 | BH17: 3 | BI17: 3 | BJ17: 2 | BK17: 1 | BL17: 2 | BM17: 3 | BN17: 0 | BO17: 0 | BP17: 3 | BQ17: 3 | BR17: 3 | BS17: 3 | BT17: 2 | BU17: 3 | BV17: 0 | BW17: 0 | BX17: 0 | BY17: 1 | BZ17: 0 | CA17: 0 | CB17: 0 | CC17: 1 | CD17: 1 | CE17: 1 | CF17: 1 | CG17: 3 | CH17: 2 | CI17: 1 | CJ17: 1 | CK17: 3 | CL17: 3 | CM17: =(SUM(AZ17:BI17)*100/40) -> 60 | CN17: =SUM(BJ17:BO17)*100/24 -> 33.333333 | CO17: =SUM(BP17:BU17)*100/24 -> 70.833333 | CP17: =SUM(BV17:BY17)*100/16 -> 6.25 | CQ17: =SUM(BZ17:CB17)*100/12 -> 0 | CR17: =SUM(CC17:CF17)*100/16 -> 25 | CS17: =SUM(CG17:CI17)*100/12 -> 50 | CT17: =SUM(CJ17:CL17)*100/12 -> 58.333333 | CU17: =SUM(CM17:CT17)/8 -> 37.96875 | CV17: 2 | CW17: 1 | CX17: 2 | CY17: 2 | CZ17: 3 | DA17: 0 | DB17: 0 | DC17: 3 | DD17: 1 | DE17: 3 | DF17: 3 | DG17: 1 | DH17: 0 | DI17: 1 | DJ17: 0 | DK17: =SUM(CV17:DA17,DC17:DI17) -> 22 | DL17: 3 | DM17: 1 | DN17: 2 | DO17: 0 | DP17: 2 | DQ17: 2 | DR17: 3 | DS17: 3 | DT17: 0 | DU17: 0 | DV17: 2 | DW17: 3 | DX17: 4 | DY17: =SUM(DL17:DX17) -> 25 | DZ17: 3 | EA17: 3 | EB17: 3 | EC17: 3 | ED17: 2 | EE17: 2 | EF17: 1 | EG17: 1 | EH17: 1 | EI17: 3 | EJ17: 3 | EK17: 3 | EL17: 2 | EM17: 0 | EN17: 0 | EO17: 0 | EP17: 0 | EQ17: 2 | ER17: 3 | ES17: 2 | ET17: 1 | EU17: 3 | EV17: 3 | EW17: 1 | EX17: 0 | EY17: 0 | EZ17: 0 | FA17: 0 | FB17: 0 | FC17: 0 | FD17: 0 | FE17: 0 | FF17: 0 | FG17: =SUM(DZ17:FF17) -> 45 | FH17: 1 | FI17: 2 | FJ17: 0 | FK17: 0 | FL17: 0 | FM17: 0 | FN17: =SUM(FH17:FM17) -> 3 | FO17: =SUM(DK17,DY17,FG17,FN17) -> 95 | FP17: 14 | FQ17: 4 | FR17: 3 | FS17: 6 | FT17: 3 | FU17: 2 | FV17: 3 | FW17: 6 | FX17: =SUM(FQ17:FW17) -> 27 | FY17: 1 | FZ17: =IF($G17<=50,$FY17+0,IF(AND($G17<60,$G17>50),$FY17+1,IF(AND($G17<70,$G17>60),$FY17+2,IF(AND($G17<80,$G17>70),$FY17+3,IF(AND($G17<90,$G17>80),$FY17+4,IF($G17>=90,$FY17+5,"")))))) -> 3 | GA17: 1
A18: 17 | B18: 1 | C18: 1 | D18: 1 | E18: 22027 | F18: 44383 | G18: =DATEDIF(E18,F18,"M")/12 -> 61.166667 | H18: 57 | I18: =G18-H18 -> 4.1666667 | J18: 0 | K18: 1 | L18: 8 | M18: 0 | N18: 3 | O18: 0 | P18: 1 | Q18: 4 | R18: 3 | S18: 1 | T18: 1 | U18: 0 | V18: 1 | W18: 1 | X18: 1 | Y18: 2 | Z18: 0 | AA18: 2 | AB18: 0 | AC18: 3 | AD18: 3 | AE18: 0 | AF18: 0 | AG18: 0 | AH18: 0 | AI18: =AJ18*ledd!$B$2+AK18*ledd!$B$3+AL18*ledd!$B$4+AM18*ledd!$B$5+AN18*ledd!$B$6+AO18*ledd!$B$7+AP18*ledd!$B$8+AQ18*ledd!$B$9+AR18*ledd!$B$10+AS18*ledd!$B$11+AT18*ledd!$B$12+AU18*ledd!$B$13+AV18*ledd!$B$14+AW18*ledd!$B$15+AX18*ledd!$B$16 -> 400 | AJ18: 400 | AK18: 0 | AL18: 0 | AM18: 0 | AN18: 0 | AO18: 0 | AP18: 0 | AQ18: 0 | AR18: 0 | AS18: 0 | AT18: 0 | AU18: 0 | AV18: 0 | AW18: 0 | AX18: 0 | AY18: 3 | AZ18: 1 | BA18: 0 | BB18: 0 | BC18: 0 | BD18: 0 | BE18: 0 | BF18: 0 | BG18: 0 | BH18: 0 | BI18: 2 | BJ18: 0 | BK18: 0 | BL18: 0 | BM18: 1 | BN18: 0 | BO18: 0 | BP18: 2 | BQ18: 1 | BR18: 2 | BS18: 1 | BT18: 1 | BU18: 0 | BV18: 0 | BW18: 0 | BX18: 0 | BY18: 0 | BZ18: 1 | CA18: 0 | CB18: 0 | CC18: 0 | CD18: 2 | CE18: 2 | CF18: 0 | CG18: 0 | CH18: 0 | CI18: 0 | CJ18: 2 | CK18: 3 | CL18: 3 | CM18: =(SUM(AZ18:BI18)*100/40) -> 7.5 | CN18: =SUM(BJ18:BO18)*100/24 -> 4.1666667 | CO18: =SUM(BP18:BU18)*100/24 -> 29.166667 | CP18: =SUM(BV18:BY18)*100/16 -> 0 | CQ18: =SUM(BZ18:CB18)*100/12 -> 8.3333333 | CR18: =SUM(CC18:CF18)*100/16 -> 25 | CS18: =SUM(CG18:CI18)*100/12 -> 0 | CT18: =SUM(CJ18:CL18)*100/12 -> 66.666667 | CU18: =SUM(CM18:CT18)/8 -> 17.604167 | CV18: 0 | CW18: 0 | CX18: 1 | CY18: 2 | CZ18: 2 | DA18: 0 | DB18: 0 | DC18: 1 | DD18: 0 | DE18: 3 | DF18: 0 | DG18: 1 | DH18: 0 | DI18: 0 | DJ18: 0 | DK18: =SUM(CV18:DA18,DC18:DI18) -> 10 | DL18: 0 | DM18: 0 | DN18: 1 | DO18: 0 | DP18: 0 | DQ18: 0 | DR18: 1 | DS18: 1 | DT18: 0 | DU18: 1 | DV18: 0 | DW18: 0 | DX18: 0 | DY18: =SUM(DL18:DX18) -> 4 | DZ18: 0 | EA18: 0 | EB18: 0 | EC18: 1 | ED18: 0 | EE18: 0 | EF18: 0 | EG18: 0 | EH18: 0 | EI18: 0 | EJ18: 0 | EK18: 0 | EL18: 0 | EM18: 0 | EN18: 0 | EO18: 0 | EP18: 0 | EQ18: 1 | ER18: 0 | ES18: 0 | ET18: 0 | EU18: 0 | EV18: 1 | EW18: 0 | EX18: 0 | EY18: 0 | EZ18: 0 | FA18: 0 | FB18: 0 | FC18: 0 | FD18: 0 | FE18: 0 | FF18: 0 | FG18: =SUM(DZ18:FF18) -> 3 | FH18: 1 | FI18: 0 | FJ18: 1 | FK18: 3 | FL18: 1 | FM18: 1 | FN18: =SUM(FH18:FM18) -> 7 | FO18: =SUM(DK18,DY18,FG18,FN18) -> 24 | FP18: 8 | FQ18: 4 | FR18: 3 | FS18: 5 | FT18: 3 | FU18: 2 | FV18: 2 | FW18: 6 | FX18: =SUM(FQ18:FW18) -> 25 | FY18: 0 | FZ18: =IF($G18<=50,$FY18+0,IF(AND($G18<60,$G18>50),$FY18+1,IF(AND($G18<70,$G18>60),$FY18+2,IF(AND($G18<80,$G18>70),$FY18+3,IF(AND($G18<90,$G18>80),$FY18+4,IF($G18>=90,$FY18+5,"")))))) -> 2 | GA18: 1
A19: 18 | B19: 1 | C19: 1 | D19: 1 | E19: 16431 | F19: 44384 | G19: =DATEDIF(E19,F19,"M")/12 -> 76.5 | H19: 73 | I19: =G19-H19 -> 3.5 | J19: 0 | K19: 1 | L19: 8 | M19: 0 | N19: 2 | O19: 0 | P19: 1 | Q19: 1 | R19: 1 | S19: 1 | T19: 1 | U19: 0 | V19: 1 | W19: 1 | X19: 3 | Y19: 3 | Z19: 0 | AA19: 2 | AB19: 0 | AC19: 1 | AD19: 6 | AE19: 1 | AF19: 1 | AG19: 0 | AH19: 0 | AI19: =AJ19*ledd!$B$2+AK19*ledd!$B$3+AL19*ledd!$B$4+AM19*ledd!$B$5+AN19*ledd!$B$6+AO19*ledd!$B$7+AP19*ledd!$B$8+AQ19*ledd!$B$9+AR19*ledd!$B$10+AS19*ledd!$B$11+AT19*ledd!$B$12+AU19*ledd!$B$13+AV19*ledd!$B$14+AW19*ledd!$B$15+AX19*ledd!$B$16 -> 435 | AJ19: 300 | AK19: 0 | AL19: 0 | AM19: 0 | AN19: 0 | AO19: 0 | AP19: 4.5 | AQ19: 0 | AR19: 0 | AS19: 0 | AT19: 0 | AU19: 0 | AV19: 0 | AW19: 0 | AX19: 0 | AY19: 2 | AZ19: 2 | BA19: 0 | BB19: 0 | BC19: 3 | BD19: 3 | BE19: 0 | BF19: 2 | BG19: 0 | BH19: 0 | BI19: 0 | BJ19: 0 | BK19: 0 | BL19: 0 | BM19: 3 | BN19: 2 | BO19: 0 | BP19: 2 | BQ19: 0 | BR19: 0 | BS19: 2 | BT19: 0 | BU19: 0 | BV19: 0 | BW19: 0 | BX19: 0 | BY19: 0 | BZ19: 0 | CA19: 0 | CB19: 0 | CC19: 0 | CD19: 2 | CE19: 4 | CF19: 0 | CG19: 2 | CH19: 0 | CI19: 0 | CJ19: 2 | CK19: 3 | CL19: 0 | CM19: =(SUM(AZ19:BI19)*100/40) -> 25 | CN19: =SUM(BJ19:BO19)*100/24 -> 20.833333 | CO19: =SUM(BP19:BU19)*100/24 -> 16.666667 | CP19: =SUM(BV19:BY19)*100/16 -> 0 | CQ19: =SUM(BZ19:CB19)*100/12 -> 0 | CR19: =SUM(CC19:CF19)*100/16 -> 37.5 | CS19: =SUM(CG19:CI19)*100/12 -> 16.666667 | CT19: =SUM(CJ19:CL19)*100/12 -> 41.666667 | CU19: =SUM(CM19:CT19)/8 -> 19.791667 | CV19: 2 | CW19: 0 | CX19: 1 | CY19: 0 | CZ19: 0 | DA19: 0 | DB19: 0 | DC19: 1 | DD19: 0 | DE19: 1 | DF19: 0 | DG19: 0 | DH19: 0 | DI19: 1 | DJ19: 0 | DK19: =SUM(CV19:DA19,DC19:DI19) -> 6 | DL19: 0 | DM19: 0 | DN19: 1 | DO19: 0 | DP19: 0 | DQ19: 0 | DR19: 3 | DS19: 3 | DT19: 0 | DU19: 1 | DV19: 0 | DW19: 0 | DX19: 0 | DY19: =SUM(DL19:DX19) -> 8 | DZ19: 0 | EA19: 0 | EB19: 0 | EC19: 1 | ED19: 0 | EE19: 0 | EF19: 0 | EG19: 0 | EH19: 0 | EI19: 0 | EJ19: 0 | EK19: 0 | EL19: 0 | EM19: 0 | EN19: 0 | EO19: 0 | EP19: 0 | EQ19: 1 | ER19: 1 | ES19: 0 | ET19: 2 | EU19: 1 | EV19: 1 | EW19: 1 | EX19: 0 | EY19: 1 | EZ19: 0 | FA19: 1 | FB19: 1 | FC19: 0 | FD19: 0 | FE19: 0 | FF19: 3 | FG19: =SUM(DZ19:FF19) -> 14 | FH19: 0 | FI19: 0 | FJ19: 0 | FK19: 0 | FL19: 0 | FM19: 0 | FN19: =SUM(FH19:FM19) -> 0 | FO19: =SUM(DK19,DY19,FG19,FN19) -> 28 | FP19: 10 | FQ19: 3 | FR19: 3 | FS19: 6 | FT19: 3 | FU19: 2 | FV19: 2 | FW19: 6 | FX19: =SUM(FQ19:FW19) -> 25 | FY19: 2 | FZ19: =IF($G19<=50,$FY19+0,IF(AND($G19<60,$G19>50),$FY19+1,IF(AND($G19<70,$G19>60),$FY19+2,IF(AND($G19<80,$G19>70),$FY19+3,IF(AND($G19<90,$G19>80),$FY19+4,IF($G19>=90,$FY19+5,"")))))) -> 5 | GA19: 0
A20: 19 | B20: 1 | C20: 1 | D20: 1 | E20: 24321 | F20: 44385 | G20: =DATEDIF(E20,F20,"M")/12 -> 54.916667 | H20: 50 | I20: =G20-H20 -> 4.9166667 | J20: 0 | K20: 0 | L20: 8 | M20: 0 | N20: 2 | O20: 0 | P20: 0 | Q20: 2 | R20: 1 | S20: 1 | T20: 1 | U20: 1 | V20: 1 | W20: 1 | X20: 1 | Y20: 1 | Z20: 0 | AA20: 1 | AB20: 0 | AC20: 0 | AD20: 0 | AE20: 1 | AF20: 0 | AG20: 0 | AH20: 1 | AI20: =AJ20*ledd!$B$2+AK20*ledd!$B$3+AL20*ledd!$B$4+AM20*ledd!$B$5+AN20*ledd!$B$6+AO20*ledd!$B$7+AP20*ledd!$B$8+AQ20*ledd!$B$9+AR20*ledd!$B$10+AS20*ledd!$B$11+AT20*ledd!$B$12+AU20*ledd!$B$13+AV20*ledd!$B$14+AW20*ledd!$B$15+AX20*ledd!$B$16 -> 730 | AJ20: 175 | AK20: 100 | AL20: 0 | AM20: 0 | AN20: 0 | AO20: 24 | AP20: 0 | AQ20: 0 | AR20: 0 | AS20: 0 | AT20: 0 | AU20: 0 | AV20: 0 | AW20: 0 | AX20: 0 | AY20: 2 | AZ20: 0 | BA20: 0 | BB20: 0 | BC20: 1 | BD20: 0 | BE20: 0 | BF20: 0 | BG20: 0 | BH20: 0 | BI20: 0 | BJ20: 0 | BK20: 0 | BL20: 0 | BM20: 1 | BN20: 0 | BO20: 1 | BP20: 0 | BQ20: 0 | BR20: 0 | BS20: 0 | BT20: 0 | BU20: 1 | BV20: 1 | BW20: 0 | BX20: 0 | BY20: 0 | BZ20: 1 | CA20: 0 | CB20: 0 | CC20: 0 | CD20: 0 | CE20: 0 | CF20: 0 | CG20: 0 | CH20: 0 | CI20: 0 | CJ20: 1 | CK20: 0 | CL20: 1 | CM20: =(SUM(AZ20:BI20)*100/40) -> 2.5 | CN20: =SUM(BJ20:BO20)*100/24 -> 8.3333333 | CO20: =SUM(BP20:BU20)*100/24 -> 4.1666667 | CP20: =SUM(BV20:BY20)*100/16 -> 6.25 | CQ20: =SUM(BZ20:CB20)*100/12 -> 8.3333333 | CR20: =SUM(CC20:CF20)*100/16 -> 0 | CS20: =SUM(CG20:CI20)*100/12 -> 0 | CT20: =SUM(CJ20:CL20)*100/12 -> 16.666667 | CU20: =SUM(CM20:CT20)/8 -> 5.78125 | CV20: 0 | CW20: 0 | CX20: 0 | CY20: 0 | CZ20: 0 | DA20: 0 | DB20: 0 | DC20: 0 | DD20: 0 | DE20: 0 | DF20: 1 | DG20: 0 | DH20: 0 | DI20: 0 | DJ20: 0 | DK20: =SUM(CV20:DA20,DC20:DI20) -> 1 | DL20: 0 | DM20: 0 | DN20: 0 | DO20: 0 | DP20: 0 | DQ20: 0 | DR20: 1 | DS20: 0 | DT20: 0 | DU20: 0 | DV20: 0 | DW20: 0 | DX20: 0 | DY20: =SUM(DL20:DX20) -> 1 | DZ20: 0 | EA20: 0 | EB20: 2 | EC20: 1 | ED20: 2 | EE20: 1 | EF20: 2 | EG20: 0 | EH20: 0 | EI20: 0 | EJ20: 0 | EK20: 0 | EL20: 0 | EM20: 0 | EN20: 0 | EO20: 0 | EP20: 1 | EQ20: 0 | ER20: 1 | ES20: 0 | ET20: 0 | EU20: 0 | EV20: 0 | EW20: 0 | EX20: 0 | EY20: 0 | EZ20: 0 | FA20: 0 | FB20: 0 | FC20: 0 | FD20: 0 | FE20: 0 | FF20: 0 | FG20: =SUM(DZ20:FF20) -> 10 | FH20: 0 | FI20: 0 | FJ20: 0 | FK20: 0 | FL20: 0 | FM20: 0 | FN20: =SUM(FH20:FM20) -> 0 | FO20: =SUM(DK20,DY20,FG20,FN20) -> 12 | FP20: 2 | FQ20: 3 | FR20: 3 | FS20: 6 | FT20: 3 | FU20: 2 | FV20: 5 | FW20: 6 | FX20: =SUM(FQ20:FW20) -> 28 | FY20: 3 | FZ20: =IF($G20<=50,$FY20+0,IF(AND($G20<60,$G20>50),$FY20+1,IF(AND($G20<70,$G20>60),$FY20+2,IF(AND($G20<80,$G20>70),$FY20+3,IF(AND($G20<90,$G20>80),$FY20+4,IF($G20>=90,$FY20+5,"")))))) -> 4 | GA20: 1
A21: 20 | B21: 1 | C21: 1 | D21: 1 | E21: 20570 | F21: 44386 | G21: =DATEDIF(E21,F21,"M")/12 -> 65.166667 | H21: 64 | I21: =G21-H21 -> 1.1666667 | J21: 0 | K21: 5 | L21: 8 | M21: 0 | N21: 1 | O21: 2 | P21: 2 | Q21: 2 | R21: 1 | S21: 0 | T21: 0 | U21: 0 | V21: 0 | W21: 1 | X21: 2 | Y21: 2 | Z21: 1 | AA21: 2 | AB21: 1 | AC21: 0 | AD21: 0 | AE21: 1 | AF21: 0 | AG21: 0 | AH21: 0 | AI21: =AJ21*ledd!$B$2+AK21*ledd!$B$3+AL21*ledd!$B$4+AM21*ledd!$B$5+AN21*ledd!$B$6+AO21*ledd!$B$7+AP21*ledd!$B$8+AQ21*ledd!$B$9+AR21*ledd!$B$10+AS21*ledd!$B$11+AT21*ledd!$B$12+AU21*ledd!$B$13+AV21*ledd!$B$14+AW21*ledd!$B$15+AX21*ledd!$B$16 -> 600 | AJ21: 600 | AK21: 0 | AL21: 0 | AM21: 0 | AN21: 0 | AO21: 0 | AP21: 0 | AQ21: 0 | AR21: 0 | AS21: 0 | AT21: 0 | AU21: 0 | AV21: 0 | AW21: 0 | AX21: 0 | AY21: 4 | AZ21: 0 | BA21: 2 | BB21: 0 | BC21: 0 | BD21: 0 | BE21: 0 | BF21: 0 | BG21: 0 | BH21: 0 | BI21: 0 | BJ21: 0 | BK21: 0 | BL21: 0 | BM21: 0 | BN21: 0 | BO21: 0 | BP21: 0 | BQ21: 0 | BR21: 1 | BS21: 2 | BT21: 1 | BU21: 1 | BV21: 0 | BW21: 0 | BX21: 0 | BY21: 0 | BZ21: 0 | CA21: 0 | CB21: 0 | CC21: 1 | CD21: 1 | CE21: 0 | CF21: 0 | CG21: 0 | CH21: 0 | CI21: 0 | CJ21: 1 | CK21: 3 | CL21: 0 | CM21: =(SUM(AZ21:BI21)*100/40) -> 5 | CN21: =SUM(BJ21:BO21)*100/24 -> 0 | CO21: =SUM(BP21:BU21)*100/24 -> 20.833333 | CP21: =SUM(BV21:BY21)*100/16 -> 0 | CQ21: =SUM(BZ21:CB21)*100/12 -> 0 | CR21: =SUM(CC21:CF21)*100/16 -> 12.5 | CS21: =SUM(CG21:CI21)*100/12 -> 0 | CT21: =SUM(CJ21:CL21)*100/12 -> 33.333333 | CU21: =SUM(CM21:CT21)/8 -> 8.9583333 | CV21: 0 | CW21: 0 | CX21: 0 | CY21: 0 | CZ21: 0 | DA21: 0 | DB21: 0 | DC21: 0 | DD21: 2 | DE21: 0 | DF21: 1 | DG21: 3 | DH21: 1 | DI21: 0 | DJ21: 0 | DK21: =SUM(CV21:DA21,DC21:DI21) -> 7 | DL21: 1 | DM21: 3 | DN21: 0 | DO21: 0 | DP21: 0 | DQ21: 0 | DR21: 0 | DS21: 0 | DT21: 0 | DU21: 1 | DV21: 0 | DW21: 1 | DX21: 1 | DY21: =SUM(DL21:DX21) -> 7 | DZ21: 1 | EA21: 2 | EB21: 2 | EC21: 2 | ED21: 1 | EE21: 1 | EF21: 1 | EG21: 1 | EH21: 1 | EI21: 2 | EJ21: 1 | EK21: 1 | EL21: 1 | EM21: 1 | EN21: 1 | EO21: 0 | EP21: 1 | EQ21: 0 | ER21: 1 | ES21: 0 | ET21: 0 | EU21: 1 | EV21: 1 | EW21: 0 | EX21: 0 | EY21: 0 | EZ21: 0 | FA21: 0 | FB21: 0 | FC21: 0 | FD21: 0 | FE21: 0 | FF21: 0 | FG21: =SUM(DZ21:FF21) -> 23 | FH21: 1 | FI21: 0 | FJ21: 1 | FK21: 0 | FL21: 0 | FM21: 0 | FN21: =SUM(FH21:FM21) -> 2 | FO21: =SUM(DK21,DY21,FG21,FN21) -> 39 | FP21: 6 | FQ21: 2 | FR21: 3 | FS21: 5 | FT21: 3 | FU21: 2 | FV21: 4 | FW21: 6 | FX21: =SUM(FQ21:FW21) -> 25 | FY21: 0 | FZ21: =IF($G21<=50,$FY21+0,IF(AND($G21<60,$G21>50),$FY21+1,IF(AND($G21<70,$G21>60),$FY21+2,IF(AND($G21<80,$G21>70),$FY21+3,IF(AND($G21<90,$G21>80),$FY21+4,IF($G21>=90,$FY21+5,"")))))) -> 2 | GA21: 0
A22: 21 | B22: 1 | C22: 1 | D22: 0 | E22: 20085 | F22: 44393 | G22: =DATEDIF(E22,F22,"M")/12 -> 66.5 | H22: 50 | I22: =G22-H22 -> 16.5 | J22: 0 | K22: 3 | L22: 1 | M22: 0 | N22: 1 | O22: 0 | P22: 1 | Q22: 4 | R22: 3 | S22: 1 | T22: 1 | U22: 0 | V22: 1 | W22: 1 | X22: 1 | Y22: 1 | Z22: 4 | AA22: 0 | AC22: 3 | AD22: 3 | AE22: 0 | AF22: 0 | AG22: 0 | AH22: 2 | AI22: =AJ22*ledd!$B$2+AK22*ledd!$B$3+AL22*ledd!$B$4+AM22*ledd!$B$5+AN22*ledd!$B$6+AO22*ledd!$B$7+AP22*ledd!$B$8+AQ22*ledd!$B$9+AR22*ledd!$B$10+AS22*ledd!$B$11+AT22*ledd!$B$12+AU22*ledd!$B$13+AV22*ledd!$B$14+AW22*ledd!$B$15+AX22*ledd!$B$16 -> 941.5 | AJ22: 550 | AK22: 100 | AL22: 0 | AM22: 0 | AN22: 0 | AO22: 0 | AP22: 0 | AQ22: 0 | AR22: 0 | AS22: 0 | AT22: 0 | AU22: 0 | AV22: 200 | AW22: 100 | AX22: 50 | AY22: 3 | AZ22: 2 | BA22: 2 | BB22: 0 | BC22: 1 | BD22: 1 | BE22: 2 | BF22: 2 | BG22: 0 | BH22: 2 | BI22: 2 | BJ22: 2 | BK22: 3 | BL22: 0 | BM22: 3 | BN22: 0 | BO22: 0 | BP22: 1 | BQ22: 0 | BR22: 0 | BS22: 0 | BT22: 1 | BU22: 0 | BV22: 0 | BW22: 0 | BX22: 0 | BY22: 0 | BZ22: 1 | CA22: 0 | CB22: 0 | CC22: 3 | CD22: 3 | CE22: 3 | CF22: 1 | CG22: 0 | CH22: 0 | CI22: 0 | CJ22: 3 | CK22: 0 | CL22: 3 | CM22: =(SUM(AZ22:BI22)*100/40) -> 35 | CN22: =SUM(BJ22:BO22)*100/24 -> 33.333333 | CO22: =SUM(BP22:BU22)*100/24 -> 8.3333333 | CP22: =SUM(BV22:BY22)*100/16 -> 0 | CQ22: =SUM(BZ22:CB22)*100/12 -> 8.3333333 | CR22: =SUM(CC22:CF22)*100/16 -> 62.5 | CS22: =SUM(CG22:CI22)*100/12 -> 0 | CT22: =SUM(CJ22:CL22)*100/12 -> 50 | CU22: =SUM(CM22:CT22)/8 -> 24.6875 | CV22: 1 | CW22: 1 | CX22: 1 | CY22: 1 | CZ22: 0 | DA22: 0 | DB22: 0 | DC22: 0 | DD22: 3 | DE22: 2 | DF22: 1 | DG22: 2 | DH22: 1 | DI22: 0 | DJ22: 0 | DK22: =SUM(CV22:DA22,DC22:DI22) -> 13 | DL22: 1 | DM22: 2 | DN22: 0 | DO22: 0 | DP22: 2 | DQ22: 1 | DR22: 3 | DS22: 3 | DT22: 2 | DU22: 0 | DV22: 0 | DW22: 2 | DX22: 3 | DY22: =SUM(DL22:DX22) -> 19 | DZ22: 2 | EA22: 2 | EB22: 0 | EC22: 0 | ED22: 0 | EE22: 0 | EF22: 0 | EG22: 3 | EH22: 3 | EI22: 0 | EJ22: 0 | EK22: 0 | EL22: 0 | EM22: 0 | EN22: 0 | EO22: 0 | EP22: 0 | EQ22: 2 | ER22: 3 | ES22: 2 | ET22: 1 | EU22: 3 | EV22: 2 | EW22: 0 | EX22: 0 | EY22: 0 | EZ22: 0 | FA22: 0 | FB22: 0 | FC22: 0 | FD22: 0 | FE22: 0 | FF22: 0 | FG22: =SUM(DZ22:FF22) -> 23 | FH22: 2 | FI22: 3 | FJ22: 2 | FK22: 3 | FL22: 1 | FM22: 1 | FN22: =SUM(FH22:FM22) -> 12 | FO22: =SUM(DK22,DY22,FG22,FN22) -> 67 | FP22: 10 | FQ22: 4 | FR22: 2 | FS22: 6 | FT22: 2 | FU22: 2 | FV22: 3 | FW22: 6 | FX22: =SUM(FQ22:FW22) -> 25 | FY22: 2 | FZ22: =IF($G22<=50,$FY22+0,IF(AND($G22<60,$G22>50),$FY22+1,IF(AND($G22<70,$G22>60),$FY22+2,IF(AND($G22<80,$G22>70),$FY22+3,IF(AND($G22<90,$G22>80),$FY22+4,IF($G22>=90,$FY22+5,"")))))) -> 4 | GA22: 1
